Workbook
Name PROJECT_Name: 'PROJECT'!$B$3
Name PROJECT_Number: 'PROJECT'!$B$4
Name PROJECT_MS4: 'PROJECT'!$B$5
Name PROJECT_AWDZ: 'PROJECT'!$B$6
Name PROJECT_DOEEReview: 'PROJECT'!$B$7
Name PROJECT_TotalLOD: 'PROJECT'!$B$8
Name PROJECT_Rainfall: 'PROJECT'!$B$9
Name PROJECT_Trigger: 'PROJECT'!$B$10
Name PROJECT_EISA: 'PROJECT'!$B$11
Name PARAMS_Rv: 'PARAMS'!$A$7:$B$11
Name PARAMS_CN: 'PARAMS'!$A$15:$E$18
Name PARAMS_Horton: 'PARAMS'!$A$22:$C$25
Name PARAMS_Depression: 'PARAMS'!$A$30:$B$32
Name PARAMS_BMP: 'PARAMS'!$A$36:$G$42
Name PARAMS_Trees: 'PARAMS'!$A$46:$C$51
Name PARAMS_Detention: 'PARAMS'!$A$55:$B$57
Name PARAMS_DetentionCN: 'PARAMS'!$A$61:$B$64
Name PARAMS_HortonLossB: 'PARAMS'!$B$26
Name PARAMS_HortonLossC: 'PARAMS'!$C$26
Name PARAMS_Ksat: 'PARAMS'!$A$68:$B$71
Name SDA_IDs: 'SDA'!$A$58:$A$67
Name CDA_IDs: 'CDA'!$A$58:$A$67

Sheet PROJECT
A1: PROJECT — Project Header (enter once)
A3: Project Name
A4: Project Number
A5: MS4 / CSS
A6: In AWDZ?
A7: DOEE Plan Review No.
A8: Total LOD Area (SF)
A9: 95th Percentile Storm Depth (in) | B9: 1.7
A10: Trigger Type
A11: EISA Section 438 Applies?

Sheet PARAMS
A1: PARAMS — Locked Lookup Tables (do not edit)
A5: Runoff Coefficients (Rv) for SWRv
A6: Land Use | B6: Rv
A7: Impervious Vehicular | B7: 0.95
A8: Impervious Non-Vehicular | B8: 0.95
A9: Compacted (Open Space) | B9: 0.25
A10: Natural (Woods) | B10: 0
A11: BMP | B11: 0
A13: TR-55 Curve Numbers by Land Use × HSG
A14: Land Use | B14: HSG A | C14: HSG B | D14: HSG C | E14: HSG D
A15: Impervious | B15: 98 | C15: 98 | D15: 98 | E15: 98
A16: BMP | B16: 98 | C16: 98 | D16: 98 | E16: 98
A17: Natural (Woods) | B17: 25 | C17: 55 | D17: 70 | E17: 77
A18: Compacted (Open Space) | B18: 39 | C18: 61 | D18: 74 | E18: 80
A20: Horton Infiltration Parameters
A21: Parameter | B21: HSG B | C21: HSG C
A22: f_max (in/hr) | B22: 5 | C22: 3
A23: f_min (in/hr) | B23: 0.3 | C23: 0.1
A24: k (1/hr) | B24: 2 | C24: 3.5
A25: Δt (hr) | B25: 0.5 | C25: 0.5
A26: Infil Loss over 24 hr (in) | B26: 9.55 | C26: 3.2285714
A28: Depression Storage
A29: Surface | B29: Depth (in)
A30: Impervious (roof/pavement) | B30: 0.1
A31: Pervious | B31: 0.2
A32: BMP surface | B32: 0.1
A34: BMP Design Parameters
A35: BMP Type | B35: Sub-Type | C35: n_media | D35: n_gravel | E35: n_reservoir | F35: Ret. Multiplier | G35: Max Drawdown (days)
A36: Permeable Pavement | B36: Enhanced | C36: — | D36: — | E36: 0.4 | F36: 1 | G36: 2
A37: Permeable Pavement | B37: Underdrained Enhanced | C37: — | D37: — | E37: 0.4 | F37: 0.6 | G37: 2
A38: Bioretention | B38: Standard | C38: 0.4 | D38: 0.4 | E38: — | F38: 0.6 | G38: 3
A39: Bioretention | B39: Enhanced | C39: 0.4 | D39: 0.4 | E39: — | F39: 1 | G39: 3
A40: Bioretention | B40: Enhanced w/ Underdrain | C40: 0.4 | D40: 0.4 | E40: — | F40: 0.6 | G40: 3
A41: Dry Swale | B41: — | C41: 0.4 | D41: 0.4 | E41: — | F41: 0.6 | G41: 3
A42: Wet Swale | B42: — | C42: — | D42: — | E42: — | F42: 0.1 | G42: —
A44: Tree Credits
A45: Code | B45: Description | C45: Rv per unit (CF)
A46: T-1 Small | B46: Planted small tree | C46: 5
A47: T-1 Large | B47: Planted large tree | C47: 10
A48: T-2 Small | B48: Preserved small tree | C48: 10
...

Sheet SDA
A1: SDA — Site Drainage Areas (one row per SDA × Land Use × HSG)
A3: SDA_ID | B3: In PROW? | C3: Land Use | D3: HSG | E3: Pre Within LOD (SF) | F3: Pre Outside LOD (SF) | G3: Post Within LOD (SF) | H3: Post Outside LOD (SF) | I3: Rv | J3: Rainfall (in) | K3: Pre SWRv Within (CF) | L3: Pre SWRv Outside (CF) | M3: Post SWRv Within (CF) | N3: Post SWRv Outside (CF)
I4: =IFERROR(VLOOKUP(C4,PARAMS_Rv,2,FALSE),"") | J4: =IF(B4="Yes",0,PROJECT_Rainfall) | K4: =IFERROR(E4*I4*J4/12,0) | L4: =IFERROR(F4*I4*J4/12,0) | M4: =IFERROR(G4*I4*J4/12,0) | N4: =IFERROR(H4*I4*J4/12,0)
I5: =IFERROR(VLOOKUP(C5,PARAMS_Rv,2,FALSE),"") | J5: =IF(B5="Yes",0,PROJECT_Rainfall) | K5: =IFERROR(E5*I5*J5/12,0) | L5: =IFERROR(F5*I5*J5/12,0) | M5: =IFERROR(G5*I5*J5/12,0) | N5: =IFERROR(H5*I5*J5/12,0)
I6: =IFERROR(VLOOKUP(C6,PARAMS_Rv,2,FALSE),"") | J6: =IF(B6="Yes",0,PROJECT_Rainfall) | K6: =IFERROR(E6*I6*J6/12,0) | L6: =IFERROR(F6*I6*J6/12,0) | M6: =IFERROR(G6*I6*J6/12,0) | N6: =IFERROR(H6*I6*J6/12,0)
I7: =IFERROR(VLOOKUP(C7,PARAMS_Rv,2,FALSE),"") | J7: =IF(B7="Yes",0,PROJECT_Rainfall) | K7: =IFERROR(E7*I7*J7/12,0) | L7: =IFERROR(F7*I7*J7/12,0) | M7: =IFERROR(G7*I7*J7/12,0) | N7: =IFERROR(H7*I7*J7/12,0)
I8: =IFERROR(VLOOKUP(C8,PARAMS_Rv,2,FALSE),"") | J8: =IF(B8="Yes",0,PROJECT_Rainfall) | K8: =IFERROR(E8*I8*J8/12,0) | L8: =IFERROR(F8*I8*J8/12,0) | M8: =IFERROR(G8*I8*J8/12,0) | N8: =IFERROR(H8*I8*J8/12,0)
I9: =IFERROR(VLOOKUP(C9,PARAMS_Rv,2,FALSE),"") | J9: =IF(B9="Yes",0,PROJECT_Rainfall) | K9: =IFERROR(E9*I9*J9/12,0) | L9: =IFERROR(F9*I9*J9/12,0) | M9: =IFERROR(G9*I9*J9/12,0) | N9: =IFERROR(H9*I9*J9/12,0)
I10: =IFERROR(VLOOKUP(C10,PARAMS_Rv,2,FALSE),"") | J10: =IF(B10="Yes",0,PROJECT_Rainfall) | K10: =IFERROR(E10*I10*J10/12,0) | L10: =IFERROR(F10*I10*J10/12,0) | M10: =IFERROR(G10*I10*J10/12,0) | N10: =IFERROR(H10*I10*J10/12,0)
I11: =IFERROR(VLOOKUP(C11,PARAMS_Rv,2,FALSE),"") | J11: =IF(B11="Yes",0,PROJECT_Rainfall) | K11: =IFERROR(E11*I11*J11/12,0) | L11: =IFERROR(F11*I11*J11/12,0) | M11: =IFERROR(G11*I11*J11/12,0) | N11: =IFERROR(H11*I11*J11/12,0)
I12: =IFERROR(VLOOKUP(C12,PARAMS_Rv,2,FALSE),"") | J12: =IF(B12="Yes",0,PROJECT_Rainfall) | K12: =IFERROR(E12*I12*J12/12,0) | L12: =IFERROR(F12*I12*J12/12,0) | M12: =IFERROR(G12*I12*J12/12,0) | N12: =IFERROR(H12*I12*J12/12,0)
I13: =IFERROR(VLOOKUP(C13,PARAMS_Rv,2,FALSE),"") | J13: =IF(B13="Yes",0,PROJECT_Rainfall) | K13: =IFERROR(E13*I13*J13/12,0) | L13: =IFERROR(F13*I13*J13/12,0) | M13: =IFERROR(G13*I13*J13/12,0) | N13: =IFERROR(H13*I13*J13/12,0)
I14: =IFERROR(VLOOKUP(C14,PARAMS_Rv,2,FALSE),"") | J14: =IF(B14="Yes",0,PROJECT_Rainfall) | K14: =IFERROR(E14*I14*J14/12,0) | L14: =IFERROR(F14*I14*J14/12,0) | M14: =IFERROR(G14*I14*J14/12,0) | N14: =IFERROR(H14*I14*J14/12,0)
I15: =IFERROR(VLOOKUP(C15,PARAMS_Rv,2,FALSE),"") | J15: =IF(B15="Yes",0,PROJECT_Rainfall) | K15: =IFERROR(E15*I15*J15/12,0) | L15: =IFERROR(F15*I15*J15/12,0) | M15: =IFERROR(G15*I15*J15/12,0) | N15: =IFERROR(H15*I15*J15/12,0)
... I53: =IFERROR(VLOOKUP(C53,PARAMS_Rv,2,FALSE),"") | J53: =IF(B53="Yes",0,PROJECT_Rainfall) | K53: =IFERROR(E53*I53*J53/12,0) | L53: =IFERROR(F53*I53*J53/12,0) | M53: =IFERROR(G53*I53*J53/12,0) | N53: =IFERROR(H53*I53*J53/12,0)
A56: SDA Summary (SUMIFS aggregation per SDA_ID)
A57: SDA_ID | B57: Pre Imp Total (SF) | C57: Pre Comp Total (SF) | D57: Pre Nat Total (SF) | E57: Pre BMP Total (SF) | F57: Post Imp Total (SF) | G57: Post Comp Total (SF) | H57: Post Nat Total (SF) | I57: Post BMP Total (SF) | J57: Post SWRv Required (CF)
A58: SDA-1 | B58: =SUMIFS($E$4:$E$53,$A$4:$A$53,A58,$C$4:$C$53,"Impervious Vehicular")+SUMIFS($E$4:$E$53,$A$4:$A$53,A58,$C$4:$C$53,"Impervious Non-Vehicular") | C58: =SUMIFS($E$4:$E$53,$A$4:$A$53,A58,$C$4:$C$53,"Compacted (Open Space)") | D58: =SUMIFS($E$4:$E$53,$A$4:$A$53,A58,$C$4:$C$53,"Natural (Woods)") | E58: =SUMIFS($E$4:$E$53,$A$4:$A$53,A58,$C$4:$C$53,"BMP") | F58: =SUMIFS($G$4:$G$53,$A$4:$A$53,A58,$C$4:$C$53,"Impervious Vehicular")+SUMIFS($G$4:$G$53,$A$4:$A$53,A58,$C$4:$C$53,"Impervious Non-Vehicular") | G58: =SUMIFS($G$4:$G$53,$A$4:$A$53,A58,$C$4:$C$53,"Compacted (Open Space)") | H58: =SUMIFS($G$4:$G$53,$A$4:$A$53,A58,$C$4:$C$53,"Natural (Woods)") | I58: =SUMIFS($G$4:$G$53,$A$4:$A$53,A58,$C$4:$C$53,"BMP") | J58: =SUMIFS($M$4:$M$53,$A$4:$A$53,A58)
A59: SDA-2 | B59: =SUMIFS($E$4:$E$53,$A$4:$A$53,A59,$C$4:$C$53,"Impervious Vehicular")+SUMIFS($E$4:$E$53,$A$4:$A$53,A59,$C$4:$C$53,"Impervious Non-Vehicular") | C59: =SUMIFS($E$4:$E$53,$A$4:$A$53,A59,$C$4:$C$53,"Compacted (Open Space)") | D59: =SUMIFS($E$4:$E$53,$A$4:$A$53,A59,$C$4:$C$53,"Natural (Woods)") | E59: =SUMIFS($E$4:$E$53,$A$4:$A$53,A59,$C$4:$C$53,"BMP") | F59: =SUMIFS($G$4:$G$53,$A$4:$A$53,A59,$C$4:$C$53,"Impervious Vehicular")+SUMIFS($G$4:$G$53,$A$4:$A$53,A59,$C$4:$C$53,"Impervious Non-Vehicular") | G59: =SUMIFS($G$4:$G$53,$A$4:$A$53,A59,$C$4:$C$53,"Compacted (Open Space)") | H59: =SUMIFS($G$4:$G$53,$A$4:$A$53,A59,$C$4:$C$53,"Natural (Woods)") | I59: =SUMIFS($G$4:$G$53,$A$4:$A$53,A59,$C$4:$C$53,"BMP") | J59: =SUMIFS($M$4:$M$53,$A$4:$A$53,A59)
A60: SDA-3 | B60: =SUMIFS($E$4:$E$53,$A$4:$A$53,A60,$C$4:$C$53,"Impervious Vehicular")+SUMIFS($E$4:$E$53,$A$4:$A$53,A60,$C$4:$C$53,"Impervious Non-Vehicular") | C60: =SUMIFS($E$4:$E$53,$A$4:$A$53,A60,$C$4:$C$53,"Compacted (Open Space)") | D60: =SUMIFS($E$4:$E$53,$A$4:$A$53,A60,$C$4:$C$53,"Natural (Woods)") | E60: =SUMIFS($E$4:$E$53,$A$4:$A$53,A60,$C$4:$C$53,"BMP") | F60: =SUMIFS($G$4:$G$53,$A$4:$A$53,A60,$C$4:$C$53,"Impervious Vehicular")+SUMIFS($G$4:$G$53,$A$4:$A$53,A60,$C$4:$C$53,"Impervious Non-Vehicular") | G60: =SUMIFS($G$4:$G$53,$A$4:$A$53,A60,$C$4:$C$53,"Compacted (Open Space)") | H60: =SUMIFS($G$4:$G$53,$A$4:$A$53,A60,$C$4:$C$53,"Natural (Woods)") | I60: =SUMIFS($G$4:$G$53,$A$4:$A$53,A60,$C$4:$C$53,"BMP") | J60: =SUMIFS($M$4:$M$53,$A$4:$A$53,A60)
A61: SDA-4 | B61: =SUMIFS($E$4:$E$53,$A$4:$A$53,A61,$C$4:$C$53,"Impervious Vehicular")+SUMIFS($E$4:$E$53,$A$4:$A$53,A61,$C$4:$C$53,"Impervious Non-Vehicular") | C61: =SUMIFS($E$4:$E$53,$A$4:$A$53,A61,$C$4:$C$53,"Compacted (Open Space)") | D61: =SUMIFS($E$4:$E$53,$A$4:$A$53,A61,$C$4:$C$53,"Natural (Woods)") | E61: =SUMIFS($E$4:$E$53,$A$4:$A$53,A61,$C$4:$C$53,"BMP") | F61: =SUMIFS($G$4:$G$53,$A$4:$A$53,A61,$C$4:$C$53,"Impervious Vehicular")+SUMIFS($G$4:$G$53,$A$4:$A$53,A61,$C$4:$C$53,"Impervious Non-Vehicular") | G61: =SUMIFS($G$4:$G$53,$A$4:$A$53,A61,$C$4:$C$53,"Compacted (Open Space)") | H61: =SUMIFS($G$4:$G$53,$A$4:$A$53,A61,$C$4:$C$53,"Natural (Woods)") | I61: =SUMIFS($G$4:$G$53,$A$4:$A$53,A61,$C$4:$C$53,"BMP") | J61: =SUMIFS($M$4:$M$53,$A$4:$A$53,A61)
A62: SDA-5 | B62: =SUMIFS($E$4:$E$53,$A$4:$A$53,A62,$C$4:$C$53,"Impervious Vehicular")+SUMIFS($E$4:$E$53,$A$4:$A$53,A62,$C$4:$C$53,"Impervious Non-Vehicular") | C62: =SUMIFS($E$4:$E$53,$A$4:$A$53,A62,$C$4:$C$53,"Compacted (Open Space)") | D62: =SUMIFS($E$4:$E$53,$A$4:$A$53,A62,$C$4:$C$53,"Natural (Woods)") | E62: =SUMIFS($E$4:$E$53,$A$4:$A$53,A62,$C$4:$C$53,"BMP") | F62: =SUMIFS($G$4:$G$53,$A$4:$A$53,A62,$C$4:$C$53,"Impervious Vehicular")+SUMIFS($G$4:$G$53,$A$4:$A$53,A62,$C$4:$C$53,"Impervious Non-Vehicular") | G62: =SUMIFS($G$4:$G$53,$A$4:$A$53,A62,$C$4:$C$53,"Compacted (Open Space)") | H62: =SUMIFS($G$4:$G$53,$A$4:$A$53,A62,$C$4:$C$53,"Natural (Woods)") | I62: =SUMIFS($G$4:$G$53,$A$4:$A$53,A62,$C$4:$C$53,"BMP") | J62: =SUMIFS($M$4:$M$53,$A$4:$A$53,A62)
A63: SDA-6 | B63: =SUMIFS($E$4:$E$53,$A$4:$A$53,A63,$C$4:$C$53,"Impervious Vehicular")+SUMIFS($E$4:$E$53,$A$4:$A$53,A63,$C$4:$C$53,"Impervious Non-Vehicular") | C63: =SUMIFS($E$4:$E$53,$A$4:$A$53,A63,$C$4:$C$53,"Compacted (Open Space)") | D63: =SUMIFS($E$4:$E$53,$A$4:$A$53,A63,$C$4:$C$53,"Natural (Woods)") | E63: =SUMIFS($E$4:$E$53,$A$4:$A$53,A63,$C$4:$C$53,"BMP") | F63: =SUMIFS($G$4:$G$53,$A$4:$A$53,A63,$C$4:$C$53,"Impervious Vehicular")+SUMIFS($G$4:$G$53,$A$4:$A$53,A63,$C$4:$C$53,"Impervious Non-Vehicular") | G63: =SUMIFS($G$4:$G$53,$A$4:$A$53,A63,$C$4:$C$53,"Compacted (Open Space)") | H63: =SUMIFS($G$4:$G$53,$A$4:$A$53,A63,$C$4:$C$53,"Natural (Woods)") | I63: =SUMIFS($G$4:$G$53,$A$4:$A$53,A63,$C$4:$C$53,"BMP") | J63: =SUMIFS($M$4:$M$53,$A$4:$A$53,A63)
A64: SDA-7 | B64: =SUMIFS($E$4:$E$53,$A$4:$A$53,A64,$C$4:$C$53,"Impervious Vehicular")+SUMIFS($E$4:$E$53,$A$4:$A$53,A64,$C$4:$C$53,"Impervious Non-Vehicular") | C64: =SUMIFS($E$4:$E$53,$A$4:$A$53,A64,$C$4:$C$53,"Compacted (Open Space)") | D64: =SUMIFS($E$4:$E$53,$A$4:$A$53,A64,$C$4:$C$53,"Natural (Woods)") | E64: =SUMIFS($E$4:$E$53,$A$4:$A$53,A64,$C$4:$C$53,"BMP") | F64: =SUMIFS($G$4:$G$53,$A$4:$A$53,A64,$C$4:$C$53,"Impervious Vehicular")+SUMIFS($G$4:$G$53,$A$4:$A$53,A64,$C$4:$C$53,"Impervious Non-Vehicular") | G64: =SUMIFS($G$4:$G$53,$A$4:$A$53,A64,$C$4:$C$53,"Compacted (Open Space)") | H64: =SUMIFS($G$4:$G$53,$A$4:$A$53,A64,$C$4:$C$53,"Natural (Woods)") | I64: =SUMIFS($G$4:$G$53,$A$4:$A$53,A64,$C$4:$C$53,"BMP") | J64: =SUMIFS($M$4:$M$53,$A$4:$A$53,A64)
A65: SDA-8 | B65: =SUMIFS($E$4:$E$53,$A$4:$A$53,A65,$C$4:$C$53,"Impervious Vehicular")+SUMIFS($E$4:$E$53,$A$4:$A$53,A65,$C$4:$C$53,"Impervious Non-Vehicular") | C65: =SUMIFS($E$4:$E$53,$A$4:$A$53,A65,$C$4:$C$53,"Compacted (Open Space)") | D65: =SUMIFS($E$4:$E$53,$A$4:$A$53,A65,$C$4:$C$53,"Natural (Woods)") | E65: =SUMIFS($E$4:$E$53,$A$4:$A$53,A65,$C$4:$C$53,"BMP") | F65: =SUMIFS($G$4:$G$53,$A$4:$A$53,A65,$C$4:$C$53,"Impervious Vehicular")+SUMIFS($G$4:$G$53,$A$4:$A$53,A65,$C$4:$C$53,"Impervious Non-Vehicular") | G65: =SUMIFS($G$4:$G$53,$A$4:$A$53,A65,$C$4:$C$53,"Compacted (Open Space)") | H65: =SUMIFS($G$4:$G$53,$A$4:$A$53,A65,$C$4:$C$53,"Natural (Woods)") | I65: =SUMIFS($G$4:$G$53,$A$4:$A$53,A65,$C$4:$C$53,"BMP") | J65: =SUMIFS($M$4:$M$53,$A$4:$A$53,A65)
A66: SDA-9 | B66: =SUMIFS($E$4:$E$53,$A$4:$A$53,A66,$C$4:$C$53,"Impervious Vehicular")+SUMIFS($E$4:$E$53,$A$4:$A$53,A66,$C$4:$C$53,"Impervious Non-Vehicular") | C66: =SUMIFS($E$4:$E$53,$A$4:$A$53,A66,$C$4:$C$53,"Compacted (Open Space)") | D66: =SUMIFS($E$4:$E$53,$A$4:$A$53,A66,$C$4:$C$53,"Natural (Woods)") | E66: =SUMIFS($E$4:$E$53,$A$4:$A$53,A66,$C$4:$C$53,"BMP") | F66: =SUMIFS($G$4:$G$53,$A$4:$A$53,A66,$C$4:$C$53,"Impervious Vehicular")+SUMIFS($G$4:$G$53,$A$4:$A$53,A66,$C$4:$C$53,"Impervious Non-Vehicular") | G66: =SUMIFS($G$4:$G$53,$A$4:$A$53,A66,$C$4:$C$53,"Compacted (Open Space)") | H66: =SUMIFS($G$4:$G$53,$A$4:$A$53,A66,$C$4:$C$53,"Natural (Woods)") | I66: =SUMIFS($G$4:$G$53,$A$4:$A$53,A66,$C$4:$C$53,"BMP") | J66: =SUMIFS($M$4:$M$53,$A$4:$A$53,A66)
A67: SDA-10 | B67: =SUMIFS($E$4:$E$53,$A$4:$A$53,A67,$C$4:$C$53,"Impervious Vehicular")+SUMIFS($E$4:$E$53,$A$4:$A$53,A67,$C$4:$C$53,"Impervious Non-Vehicular") | C67: =SUMIFS($E$4:$E$53,$A$4:$A$53,A67,$C$4:$C$53,"Compacted (Open Space)") | D67: =SUMIFS($E$4:$E$53,$A$4:$A$53,A67,$C$4:$C$53,"Natural (Woods)") | E67: =SUMIFS($E$4:$E$53,$A$4:$A$53,A67,$C$4:$C$53,"BMP") | F67: =SUMIFS($G$4:$G$53,$A$4:$A$53,A67,$C$4:$C$53,"Impervious Vehicular")+SUMIFS($G$4:$G$53,$A$4:$A$53,A67,$C$4:$C$53,"Impervious Non-Vehicular") | G67: =SUMIFS($G$4:$G$53,$A$4:$A$53,A67,$C$4:$C$53,"Compacted (Open Space)") | H67: =SUMIFS($G$4:$G$53,$A$4:$A$53,A67,$C$4:$C$53,"Natural (Woods)") | I67: =SUMIFS($G$4:$G$53,$A$4:$A$53,A67,$C$4:$C$53,"BMP") | J67: =SUMIFS($M$4:$M$53,$A$4:$A$53,A67)

Sheet CDA
A1: CDA — Contributing Drainage Areas (one row per CDA × Land Use × HSG)
A3: CDA_ID | B3: SDA_ID | C3: Land Use | D3: HSG | E3: Within LOD (SF) | F3: Outside LOD (SF) | G3: Rv | H3: CDA SWRv Within (CF) | I3: CDA SWRv Outside (CF)
G4: =IFERROR(VLOOKUP(C4,PARAMS_Rv,2,FALSE),"") | H4: =IFERROR(E4*G4*PROJECT_Rainfall/12,0) | I4: =IFERROR(F4*G4*PROJECT_Rainfall/12,0)
G5: =IFERROR(VLOOKUP(C5,PARAMS_Rv,2,FALSE),"") | H5: =IFERROR(E5*G5*PROJECT_Rainfall/12,0) | I5: =IFERROR(F5*G5*PROJECT_Rainfall/12,0)
G6: =IFERROR(VLOOKUP(C6,PARAMS_Rv,2,FALSE),"") | H6: =IFERROR(E6*G6*PROJECT_Rainfall/12,0) | I6: =IFERROR(F6*G6*PROJECT_Rainfall/12,0)
G7: =IFERROR(VLOOKUP(C7,PARAMS_Rv,2,FALSE),"") | H7: =IFERROR(E7*G7*PROJECT_Rainfall/12,0) | I7: =IFERROR(F7*G7*PROJECT_Rainfall/12,0)
G8: =IFERROR(VLOOKUP(C8,PARAMS_Rv,2,FALSE),"") | H8: =IFERROR(E8*G8*PROJECT_Rainfall/12,0) | I8: =IFERROR(F8*G8*PROJECT_Rainfall/12,0)
G9: =IFERROR(VLOOKUP(C9,PARAMS_Rv,2,FALSE),"") | H9: =IFERROR(E9*G9*PROJECT_Rainfall/12,0) | I9: =IFERROR(F9*G9*PROJECT_Rainfall/12,0)
G10: =IFERROR(VLOOKUP(C10,PARAMS_Rv,2,FALSE),"") | H10: =IFERROR(E10*G10*PROJECT_Rainfall/12,0) | I10: =IFERROR(F10*G10*PROJECT_Rainfall/12,0)
G11: =IFERROR(VLOOKUP(C11,PARAMS_Rv,2,FALSE),"") | H11: =IFERROR(E11*G11*PROJECT_Rainfall/12,0) | I11: =IFERROR(F11*G11*PROJECT_Rainfall/12,0)
G12: =IFERROR(VLOOKUP(C12,PARAMS_Rv,2,FALSE),"") | H12: =IFERROR(E12*G12*PROJECT_Rainfall/12,0) | I12: =IFERROR(F12*G12*PROJECT_Rainfall/12,0)
G13: =IFERROR(VLOOKUP(C13,PARAMS_Rv,2,FALSE),"") | H13: =IFERROR(E13*G13*PROJECT_Rainfall/12,0) | I13: =IFERROR(F13*G13*PROJECT_Rainfall/12,0)
G14: =IFERROR(VLOOKUP(C14,PARAMS_Rv,2,FALSE),"") | H14: =IFERROR(E14*G14*PROJECT_Rainfall/12,0) | I14: =IFERROR(F14*G14*PROJECT_Rainfall/12,0)
G15: =IFERROR(VLOOKUP(C15,PARAMS_Rv,2,FALSE),"") | H15: =IFERROR(E15*G15*PROJECT_Rainfall/12,0) | I15: =IFERROR(F15*G15*PROJECT_Rainfall/12,0)
... G53: =IFERROR(VLOOKUP(C53,PARAMS_Rv,2,FALSE),"") | H53: =IFERROR(E53*G53*PROJECT_Rainfall/12,0) | I53: =IFERROR(F53*G53*PROJECT_Rainfall/12,0)
A56: CDA Summary — Max BMP Credit per CDA (DOEE 1.7" cap)
A57: CDA_ID | B57: SDA_ID | C57: Total CDA Within LOD (SF) | D57: Max BMP Credit (CF)
A58: CDA-1 | B58: =IFERROR(INDEX($B$4:$B$53,MATCH(A58,$A$4:$A$53,0)),"") | C58: =SUMIFS($E$4:$E$53,$A$4:$A$53,A58) | D58: =C58*1.7/12
A59: CDA-2 | B59: =IFERROR(INDEX($B$4:$B$53,MATCH(A59,$A$4:$A$53,0)),"") | C59: =SUMIFS($E$4:$E$53,$A$4:$A$53,A59) | D59: =C59*1.7/12
A60: CDA-3 | B60: =IFERROR(INDEX($B$4:$B$53,MATCH(A60,$A$4:$A$53,0)),"") | C60: =SUMIFS($E$4:$E$53,$A$4:$A$53,A60) | D60: =C60*1.7/12
A61: CDA-4 | B61: =IFERROR(INDEX($B$4:$B$53,MATCH(A61,$A$4:$A$53,0)),"") | C61: =SUMIFS($E$4:$E$53,$A$4:$A$53,A61) | D61: =C61*1.7/12
A62: CDA-5 | B62: =IFERROR(INDEX($B$4:$B$53,MATCH(A62,$A$4:$A$53,0)),"") | C62: =SUMIFS($E$4:$E$53,$A$4:$A$53,A62) | D62: =C62*1.7/12
A63: CDA-6 | B63: =IFERROR(INDEX($B$4:$B$53,MATCH(A63,$A$4:$A$53,0)),"") | C63: =SUMIFS($E$4:$E$53,$A$4:$A$53,A63) | D63: =C63*1.7/12
A64: CDA-7 | B64: =IFERROR(INDEX($B$4:$B$53,MATCH(A64,$A$4:$A$53,0)),"") | C64: =SUMIFS($E$4:$E$53,$A$4:$A$53,A64) | D64: =C64*1.7/12
A65: CDA-8 | B65: =IFERROR(INDEX($B$4:$B$53,MATCH(A65,$A$4:$A$53,0)),"") | C65: =SUMIFS($E$4:$E$53,$A$4:$A$53,A65) | D65: =C65*1.7/12
A66: CDA-9 | B66: =IFERROR(INDEX($B$4:$B$53,MATCH(A66,$A$4:$A$53,0)),"") | C66: =SUMIFS($E$4:$E$53,$A$4:$A$53,A66) | D66: =C66*1.7/12
A67: CDA-10 | B67: =IFERROR(INDEX($B$4:$B$53,MATCH(A67,$A$4:$A$53,0)),"") | C67: =SUMIFS($E$4:$E$53,$A$4:$A$53,A67) | D67: =C67*1.7/12

Sheet BMP
A1: BMP — Best Management Practices (sizing + retention credits)
A2: Ksat auto-populates from PARAMS_Ksat (by CDA dominant HSG) only for Enhanced sub-types. Standard/lined BMPs show 0 (no native-soil infiltration). Override with a site-measured value if testing is available.
A3: BMP Name | B3: SDA_ID | C3: CDA_ID | D3: BMP Type | E3: Sub-Type | F3: PP Surface Area Aₚ (SF) | G3: PP Reservoir dₚ (ft) | H3: PP Sump d_sump (ft) | I3: PP Ksat (ft/day) | J3: PP n_reservoir | K3: PP Sv (CF) | L3: PP Drawdown (days) | M3: PP Drawdown ≤ 2? | N3: Bio SA_top (SF) | O3: Bio SA_bot (SF) | P3: Bio SA_avg (SF) | Q3: Bio d_media (ft) | R3: Bio n_media | S3: Bio d_gravel (ft) | T3: Bio n_gravel | U3: Bio d_pond (ft) | V3: Bio Ksat (ft/day) | W3: Bio Sv (CF) | X3: Bio Drawdown (days) | Y3: WS Pool Vol (CF) | Z3: WS ED Vol (CF) | AA3: WS Sv (CF) | AB3: # Planted Small | AC3: # Planted Large | AD3: # Preserved Small | AE3: # Preserved Large | AF3: # Preserved Special | AG3: # Preserved Heritage | AH3: Tree Rv Total (CF) | AI3: Sv Total (CF) | AJ3: Ret. Multiplier | AK3: Rv Uncapped (CF) | AL3: Max BMP Credit (CF) | AM3: Rv Applied (CF)
I4: =IFERROR(IF(OR(E4="Enhanced",E4="Underdrained Enhanced"),VLOOKUP(IF(SUMIFS('CDA'!$E$4:$E$53,'CDA'!$A$4:$A$53,C4,'CDA'!$D$4:$D$53,"D")>0,"D",IF(SUMIFS('CDA'!$E$4:$E$53,'CDA'!$A$4:$A$53,C4,'CDA'!$D$4:$D$53,"C")>0,"C",IF(SUMIFS('CDA'!$E$4:$E$53,'CDA'!$A$4:$A$53,C4,'CDA'!$D$4:$D$53,"B")>0,"B",IF(SUMIFS('CDA'!$E$4:$E$53,'CDA'!$A$4:$A$53,C4,'CDA'!$D$4:$D$53,"A")>0,"A","")))),PARAMS_Ksat,2,FALSE),0),0) | J4: =IFERROR(IF(AND(D4="Permeable Pavement",E4="Enhanced"),INDEX(PARAMS_BMP,1,5),IF(AND(D4="Permeable Pavement",E4="Underdrained Enhanced"),INDEX(PARAMS_BMP,2,5),IF(AND(D4="Bioretention",E4="Standard"),INDEX(PARAMS_BMP,3,5),IF(AND(D4="Bioretention",E4="Enhanced"),INDEX(PARAMS_BMP,4,5),IF(AND(D4="Bioretention",E4="Enhanced w/ Underdrain"),INDEX(PARAMS_BMP,5,5),IF(AND(D4="Dry Swale",E4="—"),INDEX(PARAMS_BMP,6,5),IF(AND(D4="Wet Swale",E4="—"),INDEX(PARAMS_BMP,7,5),""))))))),"") | K4: =IFERROR(F4*G4*J4,0) | L4: =IFERROR(IF(I4=0,"",G4/I4),"") | M4: =IFERROR(IF(L4="","",IF(L4<=2,"✓","✗")),"") | P4: =IFERROR((N4+O4)/2,0) | R4: =IFERROR(IF(AND(D4="Permeable Pavement",E4="Enhanced"),INDEX(PARAMS_BMP,1,3),IF(AND(D4="Permeable Pavement",E4="Underdrained Enhanced"),INDEX(PARAMS_BMP,2,3),IF(AND(D4="Bioretention",E4="Standard"),INDEX(PARAMS_BMP,3,3),IF(AND(D4="Bioretention",E4="Enhanced"),INDEX(PARAMS_BMP,4,3),IF(AND(D4="Bioretention",E4="Enhanced w/ Underdrain"),INDEX(PARAMS_BMP,5,3),IF(AND(D4="Dry Swale",E4="—"),INDEX(PARAMS_BMP,6,3),IF(AND(D4="Wet Swale",E4="—"),INDEX(PARAMS_BMP,7,3),""))))))),"") | T4: =IFERROR(IF(AND(D4="Permeable Pavement",E4="Enhanced"),INDEX(PARAMS_BMP,1,4),IF(AND(D4="Permeable Pavement",E4="Underdrained Enhanced"),INDEX(PARAMS_BMP,2,4),IF(AND(D4="Bioretention",E4="Standard"),INDEX(PARAMS_BMP,3,4),IF(AND(D4="Bioretention",E4="Enhanced"),INDEX(PARAMS_BMP,4,4),IF(AND(D4="Bioretention",E4="Enhanced w/ Underdrain"),INDEX(PARAMS_BMP,5,4),IF(AND(D4="Dry Swale",E4="—"),INDEX(PARAMS_BMP,6,4),IF(AND(D4="Wet Swale",E4="—"),INDEX(PARAMS_BMP,7,4),""))))))),"") | V4: =IFERROR(IF(OR(E4="Enhanced",E4="Enhanced w/ Underdrain"),VLOOKUP(IF(SUMIFS('CDA'!$E$4:$E$53,'CDA'!$A$4:$A$53,C4,'CDA'!$D$4:$D$53,"D")>0,"D",IF(SUMIFS('CDA'!$E$4:$E$53,'CDA'!$A$4:$A$53,C4,'CDA'!$D$4:$D$53,"C")>0,"C",IF(SUMIFS('CDA'!$E$4:$E$53,'CDA'!$A$4:$A$53,C4,'CDA'!$D$4:$D$53,"B")>0,"B",IF(SUMIFS('CDA'!$E$4:$E$53,'CDA'!$A$4:$A$53,C4,'CDA'!$D$4:$D$53,"A")>0,"A","")))),PARAMS_Ksat,2,FALSE),0),0) | W4: =IFERROR(P4*(Q4*R4+S4*T4+U4),0) | X4: =IFERROR(IF(V4=0,"",(Q4+S4)/V4),"") | AA4: =IFERROR(Y4+Z4,0) | AH4: =IFERROR(AB4*INDEX(PARAMS_Trees,1,3)+AC4*INDEX(PARAMS_Trees,2,3)+AD4*INDEX(PARAMS_Trees,3,3)+AE4*INDEX(PARAMS_Trees,4,3)+AF4*INDEX(PARAMS_Trees,5,3)+AG4*INDEX(PARAMS_Trees,6,3),0) | AI4: =IFERROR(K4+W4+AA4,0) | AJ4: =IFERROR(IF(AND(D4="Permeable Pavement",E4="Enhanced"),INDEX(PARAMS_BMP,1,6),IF(AND(D4="Permeable Pavement",E4="Underdrained Enhanced"),INDEX(PARAMS_BMP,2,6),IF(AND(D4="Bioretention",E4="Standard"),INDEX(PARAMS_BMP,3,6),IF(AND(D4="Bioretention",E4="Enhanced"),INDEX(PARAMS_BMP,4,6),IF(AND(D4="Bioretention",E4="Enhanced w/ Underdrain"),INDEX(PARAMS_BMP,5,6),IF(AND(D4="Dry Swale",E4="—"),INDEX(PARAMS_BMP,6,6),IF(AND(D4="Wet Swale",E4="—"),INDEX(PARAMS_BMP,7,6),""))))))),"") | AK4: =IFERROR(AI4*AJ4+AH4,0) | AL4: =IFERROR(VLOOKUP(C4,'CDA'!$A$58:$D$67,4,FALSE),0) | AM4: =IFERROR(IF(AL4=0,AK4,MIN(AK4,AL4)),0)
I5: =IFERROR(IF(OR(E5="Enhanced",E5="Underdrained Enhanced"),VLOOKUP(IF(SUMIFS('CDA'!$E$4:$E$53,'CDA'!$A$4:$A$53,C5,'CDA'!$D$4:$D$53,"D")>0,"D",IF(SUMIFS('CDA'!$E$4:$E$53,'CDA'!$A$4:$A$53,C5,'CDA'!$D$4:$D$53,"C")>0,"C",IF(SUMIFS('CDA'!$E$4:$E$53,'CDA'!$A$4:$A$53,C5,'CDA'!$D$4:$D$53,"B")>0,"B",IF(SUMIFS('CDA'!$E$4:$E$53,'CDA'!$A$4:$A$53,C5,'CDA'!$D$4:$D$53,"A")>0,"A","")))),PARAMS_Ksat,2,FALSE),0),0) | J5: =IFERROR(IF(AND(D5="Permeable Pavement",E5="Enhanced"),INDEX(PARAMS_BMP,1,5),IF(AND(D5="Permeable Pavement",E5="Underdrained Enhanced"),INDEX(PARAMS_BMP,2,5),IF(AND(D5="Bioretention",E5="Standard"),INDEX(PARAMS_BMP,3,5),IF(AND(D5="Bioretention",E5="Enhanced"),INDEX(PARAMS_BMP,4,5),IF(AND(D5="Bioretention",E5="Enhanced w/ Underdrain"),INDEX(PARAMS_BMP,5,5),IF(AND(D5="Dry Swale",E5="—"),INDEX(PARAMS_BMP,6,5),IF(AND(D5="Wet Swale",E5="—"),INDEX(PARAMS_BMP,7,5),""))))))),"") | K5: =IFERROR(F5*G5*J5,0) | L5: =IFERROR(IF(I5=0,"",G5/I5),"") | M5: =IFERROR(IF(L5="","",IF(L5<=2,"✓","✗")),"") | P5: =IFERROR((N5+O5)/2,0) | R5: =IFERROR(IF(AND(D5="Permeable Pavement",E5="Enhanced"),INDEX(PARAMS_BMP,1,3),IF(AND(D5="Permeable Pavement",E5="Underdrained Enhanced"),INDEX(PARAMS_BMP,2,3),IF(AND(D5="Bioretention",E5="Standard"),INDEX(PARAMS_BMP,3,3),IF(AND(D5="Bioretention",E5="Enhanced"),INDEX(PARAMS_BMP,4,3),IF(AND(D5="Bioretention",E5="Enhanced w/ Underdrain"),INDEX(PARAMS_BMP,5,3),IF(AND(D5="Dry Swale",E5="—"),INDEX(PARAMS_BMP,6,3),IF(AND(D5="Wet Swale",E5="—"),INDEX(PARAMS_BMP,7,3),""))))))),"") | T5: =IFERROR(IF(AND(D5="Permeable Pavement",E5="Enhanced"),INDEX(PARAMS_BMP,1,4),IF(AND(D5="Permeable Pavement",E5="Underdrained Enhanced"),INDEX(PARAMS_BMP,2,4),IF(AND(D5="Bioretention",E5="Standard"),INDEX(PARAMS_BMP,3,4),IF(AND(D5="Bioretention",E5="Enhanced"),INDEX(PARAMS_BMP,4,4),IF(AND(D5="Bioretention",E5="Enhanced w/ Underdrain"),INDEX(PARAMS_BMP,5,4),IF(AND(D5="Dry Swale",E5="—"),INDEX(PARAMS_BMP,6,4),IF(AND(D5="Wet Swale",E5="—"),INDEX(PARAMS_BMP,7,4),""))))))),"") | V5: =IFERROR(IF(OR(E5="Enhanced",E5="Enhanced w/ Underdrain"),VLOOKUP(IF(SUMIFS('CDA'!$E$4:$E$53,'CDA'!$A$4:$A$53,C5,'CDA'!$D$4:$D$53,"D")>0,"D",IF(SUMIFS('CDA'!$E$4:$E$53,'CDA'!$A$4:$A$53,C5,'CDA'!$D$4:$D$53,"C")>0,"C",IF(SUMIFS('CDA'!$E$4:$E$53,'CDA'!$A$4:$A$53,C5,'CDA'!$D$4:$D$53,"B")>0,"B",IF(SUMIFS('CDA'!$E$4:$E$53,'CDA'!$A$4:$A$53,C5,'CDA'!$D$4:$D$53,"A")>0,"A","")))),PARAMS_Ksat,2,FALSE),0),0) | W5: =IFERROR(P5*(Q5*R5+S5*T5+U5),0) | X5: =IFERROR(IF(V5=0,"",(Q5+S5)/V5),"") | AA5: =IFERROR(Y5+Z5,0) | AH5: =IFERROR(AB5*INDEX(PARAMS_Trees,1,3)+AC5*INDEX(PARAMS_Trees,2,3)+AD5*INDEX(PARAMS_Trees,3,3)+AE5*INDEX(PARAMS_Trees,4,3)+AF5*INDEX(PARAMS_Trees,5,3)+AG5*INDEX(PARAMS_Trees,6,3),0) | AI5: =IFERROR(K5+W5+AA5,0) | AJ5: =IFERROR(IF(AND(D5="Permeable Pavement",E5="Enhanced"),INDEX(PARAMS_BMP,1,6),IF(AND(D5="Permeable Pavement",E5="Underdrained Enhanced"),INDEX(PARAMS_BMP,2,6),IF(AND(D5="Bioretention",E5="Standard"),INDEX(PARAMS_BMP,3,6),IF(AND(D5="Bioretention",E5="Enhanced"),INDEX(PARAMS_BMP,4,6),IF(AND(D5="Bioretention",E5="Enhanced w/ Underdrain"),INDEX(PARAMS_BMP,5,6),IF(AND(D5="Dry Swale",E5="—"),INDEX(PARAMS_BMP,6,6),IF(AND(D5="Wet Swale",E5="—"),INDEX(PARAMS_BMP,7,6),""))))))),"") | AK5: =IFERROR(AI5*AJ5+AH5,0) | AL5: =IFERROR(VLOOKUP(C5,'CDA'!$A$58:$D$67,4,FALSE),0) | AM5: =IFERROR(IF(AL5=0,AK5,MIN(AK5,AL5)),0)
I6: =IFERROR(IF(OR(E6="Enhanced",E6="Underdrained Enhanced"),VLOOKUP(IF(SUMIFS('CDA'!$E$4:$E$53,'CDA'!$A$4:$A$53,C6,'CDA'!$D$4:$D$53,"D")>0,"D",IF(SUMIFS('CDA'!$E$4:$E$53,'CDA'!$A$4:$A$53,C6,'CDA'!$D$4:$D$53,"C")>0,"C",IF(SUMIFS('CDA'!$E$4:$E$53,'CDA'!$A$4:$A$53,C6,'CDA'!$D$4:$D$53,"B")>0,"B",IF(SUMIFS('CDA'!$E$4:$E$53,'CDA'!$A$4:$A$53,C6,'CDA'!$D$4:$D$53,"A")>0,"A","")))),PARAMS_Ksat,2,FALSE),0),0) | J6: =IFERROR(IF(AND(D6="Permeable Pavement",E6="Enhanced"),INDEX(PARAMS_BMP,1,5),IF(AND(D6="Permeable Pavement",E6="Underdrained Enhanced"),INDEX(PARAMS_BMP,2,5),IF(AND(D6="Bioretention",E6="Standard"),INDEX(PARAMS_BMP,3,5),IF(AND(D6="Bioretention",E6="Enhanced"),INDEX(PARAMS_BMP,4,5),IF(AND(D6="Bioretention",E6="Enhanced w/ Underdrain"),INDEX(PARAMS_BMP,5,5),IF(AND(D6="Dry Swale",E6="—"),INDEX(PARAMS_BMP,6,5),IF(AND(D6="Wet Swale",E6="—"),INDEX(PARAMS_BMP,7,5),""))))))),"") | K6: =IFERROR(F6*G6*J6,0) | L6: =IFERROR(IF(I6=0,"",G6/I6),"") | M6: =IFERROR(IF(L6="","",IF(L6<=2,"✓","✗")),"") | P6: =IFERROR((N6+O6)/2,0) | R6: =IFERROR(IF(AND(D6="Permeable Pavement",E6="Enhanced"),INDEX(PARAMS_BMP,1,3),IF(AND(D6="Permeable Pavement",E6="Underdrained Enhanced"),INDEX(PARAMS_BMP,2,3),IF(AND(D6="Bioretention",E6="Standard"),INDEX(PARAMS_BMP,3,3),IF(AND(D6="Bioretention",E6="Enhanced"),INDEX(PARAMS_BMP,4,3),IF(AND(D6="Bioretention",E6="Enhanced w/ Underdrain"),INDEX(PARAMS_BMP,5,3),IF(AND(D6="Dry Swale",E6="—"),INDEX(PARAMS_BMP,6,3),IF(AND(D6="Wet Swale",E6="—"),INDEX(PARAMS_BMP,7,3),""))))))),"") | T6: =IFERROR(IF(AND(D6="Permeable Pavement",E6="Enhanced"),INDEX(PARAMS_BMP,1,4),IF(AND(D6="Permeable Pavement",E6="Underdrained Enhanced"),INDEX(PARAMS_BMP,2,4),IF(AND(D6="Bioretention",E6="Standard"),INDEX(PARAMS_BMP,3,4),IF(AND(D6="Bioretention",E6="Enhanced"),INDEX(PARAMS_BMP,4,4),IF(AND(D6="Bioretention",E6="Enhanced w/ Underdrain"),INDEX(PARAMS_BMP,5,4),IF(AND(D6="Dry Swale",E6="—"),INDEX(PARAMS_BMP,6,4),IF(AND(D6="Wet Swale",E6="—"),INDEX(PARAMS_BMP,7,4),""))))))),"") | V6: =IFERROR(IF(OR(E6="Enhanced",E6="Enhanced w/ Underdrain"),VLOOKUP(IF(SUMIFS('CDA'!$E$4:$E$53,'CDA'!$A$4:$A$53,C6,'CDA'!$D$4:$D$53,"D")>0,"D",IF(SUMIFS('CDA'!$E$4:$E$53,'CDA'!$A$4:$A$53,C6,'CDA'!$D$4:$D$53,"C")>0,"C",IF(SUMIFS('CDA'!$E$4:$E$53,'CDA'!$A$4:$A$53,C6,'CDA'!$D$4:$D$53,"B")>0,"B",IF(SUMIFS('CDA'!$E$4:$E$53,'CDA'!$A$4:$A$53,C6,'CDA'!$D$4:$D$53,"A")>0,"A","")))),PARAMS_Ksat,2,FALSE),0),0) | W6: =IFERROR(P6*(Q6*R6+S6*T6+U6),0) | X6: =IFERROR(IF(V6=0,"",(Q6+S6)/V6),"") | AA6: =IFERROR(Y6+Z6,0) | AH6: =IFERROR(AB6*INDEX(PARAMS_Trees,1,3)+AC6*INDEX(PARAMS_Trees,2,3)+AD6*INDEX(PARAMS_Trees,3,3)+AE6*INDEX(PARAMS_Trees,4,3)+AF6*INDEX(PARAMS_Trees,5,3)+AG6*INDEX(PARAMS_Trees,6,3),0) | AI6: =IFERROR(K6+W6+AA6,0) | AJ6: =IFERROR(IF(AND(D6="Permeable Pavement",E6="Enhanced"),INDEX(PARAMS_BMP,1,6),IF(AND(D6="Permeable Pavement",E6="Underdrained Enhanced"),INDEX(PARAMS_BMP,2,6),IF(AND(D6="Bioretention",E6="Standard"),INDEX(PARAMS_BMP,3,6),IF(AND(D6="Bioretention",E6="Enhanced"),INDEX(PARAMS_BMP,4,6),IF(AND(D6="Bioretention",E6="Enhanced w/ Underdrain"),INDEX(PARAMS_BMP,5,6),IF(AND(D6="Dry Swale",E6="—"),INDEX(PARAMS_BMP,6,6),IF(AND(D6="Wet Swale",E6="—"),INDEX(PARAMS_BMP,7,6),""))))))),"") | AK6: =IFERROR(AI6*AJ6+AH6,0) | AL6: =IFERROR(VLOOKUP(C6,'CDA'!$A$58:$D$67,4,FALSE),0) | AM6: =IFERROR(IF(AL6=0,AK6,MIN(AK6,AL6)),0)
I7: =IFERROR(IF(OR(E7="Enhanced",E7="Underdrained Enhanced"),VLOOKUP(IF(SUMIFS('CDA'!$E$4:$E$53,'CDA'!$A$4:$A$53,C7,'CDA'!$D$4:$D$53,"D")>0,"D",IF(SUMIFS('CDA'!$E$4:$E$53,'CDA'!$A$4:$A$53,C7,'CDA'!$D$4:$D$53,"C")>0,"C",IF(SUMIFS('CDA'!$E$4:$E$53,'CDA'!$A$4:$A$53,C7,'CDA'!$D$4:$D$53,"B")>0,"B",IF(SUMIFS('CDA'!$E$4:$E$53,'CDA'!$A$4:$A$53,C7,'CDA'!$D$4:$D$53,"A")>0,"A","")))),PARAMS_Ksat,2,FALSE),0),0) | J7: =IFERROR(IF(AND(D7="Permeable Pavement",E7="Enhanced"),INDEX(PARAMS_BMP,1,5),IF(AND(D7="Permeable Pavement",E7="Underdrained Enhanced"),INDEX(PARAMS_BMP,2,5),IF(AND(D7="Bioretention",E7="Standard"),INDEX(PARAMS_BMP,3,5),IF(AND(D7="Bioretention",E7="Enhanced"),INDEX(PARAMS_BMP,4,5),IF(AND(D7="Bioretention",E7="Enhanced w/ Underdrain"),INDEX(PARAMS_BMP,5,5),IF(AND(D7="Dry Swale",E7="—"),INDEX(PARAMS_BMP,6,5),IF(AND(D7="Wet Swale",E7="—"),INDEX(PARAMS_BMP,7,5),""))))))),"") | K7: =IFERROR(F7*G7*J7,0) | L7: =IFERROR(IF(I7=0,"",G7/I7),"") | M7: =IFERROR(IF(L7="","",IF(L7<=2,"✓","✗")),"") | P7: =IFERROR((N7+O7)/2,0) | R7: =IFERROR(IF(AND(D7="Permeable Pavement",E7="Enhanced"),INDEX(PARAMS_BMP,1,3),IF(AND(D7="Permeable Pavement",E7="Underdrained Enhanced"),INDEX(PARAMS_BMP,2,3),IF(AND(D7="Bioretention",E7="Standard"),INDEX(PARAMS_BMP,3,3),IF(AND(D7="Bioretention",E7="Enhanced"),INDEX(PARAMS_BMP,4,3),IF(AND(D7="Bioretention",E7="Enhanced w/ Underdrain"),INDEX(PARAMS_BMP,5,3),IF(AND(D7="Dry Swale",E7="—"),INDEX(PARAMS_BMP,6,3),IF(AND(D7="Wet Swale",E7="—"),INDEX(PARAMS_BMP,7,3),""))))))),"") | T7: =IFERROR(IF(AND(D7="Permeable Pavement",E7="Enhanced"),INDEX(PARAMS_BMP,1,4),IF(AND(D7="Permeable Pavement",E7="Underdrained Enhanced"),INDEX(PARAMS_BMP,2,4),IF(AND(D7="Bioretention",E7="Standard"),INDEX(PARAMS_BMP,3,4),IF(AND(D7="Bioretention",E7="Enhanced"),INDEX(PARAMS_BMP,4,4),IF(AND(D7="Bioretention",E7="Enhanced w/ Underdrain"),INDEX(PARAMS_BMP,5,4),IF(AND(D7="Dry Swale",E7="—"),INDEX(PARAMS_BMP,6,4),IF(AND(D7="Wet Swale",E7="—"),INDEX(PARAMS_BMP,7,4),""))))))),"") | V7: =IFERROR(IF(OR(E7="Enhanced",E7="Enhanced w/ Underdrain"),VLOOKUP(IF(SUMIFS('CDA'!$E$4:$E$53,'CDA'!$A$4:$A$53,C7,'CDA'!$D$4:$D$53,"D")>0,"D",IF(SUMIFS('CDA'!$E$4:$E$53,'CDA'!$A$4:$A$53,C7,'CDA'!$D$4:$D$53,"C")>0,"C",IF(SUMIFS('CDA'!$E$4:$E$53,'CDA'!$A$4:$A$53,C7,'CDA'!$D$4:$D$53,"B")>0,"B",IF(SUMIFS('CDA'!$E$4:$E$53,'CDA'!$A$4:$A$53,C7,'CDA'!$D$4:$D$53,"A")>0,"A","")))),PARAMS_Ksat,2,FALSE),0),0) | W7: =IFERROR(P7*(Q7*R7+S7*T7+U7),0) | X7: =IFERROR(IF(V7=0,"",(Q7+S7)/V7),"") | AA7: =IFERROR(Y7+Z7,0) | AH7: =IFERROR(AB7*INDEX(PARAMS_Trees,1,3)+AC7*INDEX(PARAMS_Trees,2,3)+AD7*INDEX(PARAMS_Trees,3,3)+AE7*INDEX(PARAMS_Trees,4,3)+AF7*INDEX(PARAMS_Trees,5,3)+AG7*INDEX(PARAMS_Trees,6,3),0) | AI7: =IFERROR(K7+W7+AA7,0) | AJ7: =IFERROR(IF(AND(D7="Permeable Pavement",E7="Enhanced"),INDEX(PARAMS_BMP,1,6),IF(AND(D7="Permeable Pavement",E7="Underdrained Enhanced"),INDEX(PARAMS_BMP,2,6),IF(AND(D7="Bioretention",E7="Standard"),INDEX(PARAMS_BMP,3,6),IF(AND(D7="Bioretention",E7="Enhanced"),INDEX(PARAMS_BMP,4,6),IF(AND(D7="Bioretention",E7="Enhanced w/ Underdrain"),INDEX(PARAMS_BMP,5,6),IF(AND(D7="Dry Swale",E7="—"),INDEX(PARAMS_BMP,6,6),IF(AND(D7="Wet Swale",E7="—"),INDEX(PARAMS_BMP,7,6),""))))))),"") | AK7: =IFERROR(AI7*AJ7+AH7,0) | AL7: =IFERROR(VLOOKUP(C7,'CDA'!$A$58:$D$67,4,FALSE),0) | AM7: =IFERROR(IF(AL7=0,AK7,MIN(AK7,AL7)),0)
I8: =IFERROR(IF(OR(E8="Enhanced",E8="Underdrained Enhanced"),VLOOKUP(IF(SUMIFS('CDA'!$E$4:$E$53,'CDA'!$A$4:$A$53,C8,'CDA'!$D$4:$D$53,"D")>0,"D",IF(SUMIFS('CDA'!$E$4:$E$53,'CDA'!$A$4:$A$53,C8,'CDA'!$D$4:$D$53,"C")>0,"C",IF(SUMIFS('CDA'!$E$4:$E$53,'CDA'!$A$4:$A$53,C8,'CDA'!$D$4:$D$53,"B")>0,"B",IF(SUMIFS('CDA'!$E$4:$E$53,'CDA'!$A$4:$A$53,C8,'CDA'!$D$4:$D$53,"A")>0,"A","")))),PARAMS_Ksat,2,FALSE),0),0) | J8: =IFERROR(IF(AND(D8="Permeable Pavement",E8="Enhanced"),INDEX(PARAMS_BMP,1,5),IF(AND(D8="Permeable Pavement",E8="Underdrained Enhanced"),INDEX(PARAMS_BMP,2,5),IF(AND(D8="Bioretention",E8="Standard"),INDEX(PARAMS_BMP,3,5),IF(AND(D8="Bioretention",E8="Enhanced"),INDEX(PARAMS_BMP,4,5),IF(AND(D8="Bioretention",E8="Enhanced w/ Underdrain"),INDEX(PARAMS_BMP,5,5),IF(AND(D8="Dry Swale",E8="—"),INDEX(PARAMS_BMP,6,5),IF(AND(D8="Wet Swale",E8="—"),INDEX(PARAMS_BMP,7,5),""))))))),"") | K8: =IFERROR(F8*G8*J8,0) | L8: =IFERROR(IF(I8=0,"",G8/I8),"") | M8: =IFERROR(IF(L8="","",IF(L8<=2,"✓","✗")),"") | P8: =IFERROR((N8+O8)/2,0) | R8: =IFERROR(IF(AND(D8="Permeable Pavement",E8="Enhanced"),INDEX(PARAMS_BMP,1,3),IF(AND(D8="Permeable Pavement",E8="Underdrained Enhanced"),INDEX(PARAMS_BMP,2,3),IF(AND(D8="Bioretention",E8="Standard"),INDEX(PARAMS_BMP,3,3),IF(AND(D8="Bioretention",E8="Enhanced"),INDEX(PARAMS_BMP,4,3),IF(AND(D8="Bioretention",E8="Enhanced w/ Underdrain"),INDEX(PARAMS_BMP,5,3),IF(AND(D8="Dry Swale",E8="—"),INDEX(PARAMS_BMP,6,3),IF(AND(D8="Wet Swale",E8="—"),INDEX(PARAMS_BMP,7,3),""))))))),"") | T8: =IFERROR(IF(AND(D8="Permeable Pavement",E8="Enhanced"),INDEX(PARAMS_BMP,1,4),IF(AND(D8="Permeable Pavement",E8="Underdrained Enhanced"),INDEX(PARAMS_BMP,2,4),IF(AND(D8="Bioretention",E8="Standard"),INDEX(PARAMS_BMP,3,4),IF(AND(D8="Bioretention",E8="Enhanced"),INDEX(PARAMS_BMP,4,4),IF(AND(D8="Bioretention",E8="Enhanced w/ Underdrain"),INDEX(PARAMS_BMP,5,4),IF(AND(D8="Dry Swale",E8="—"),INDEX(PARAMS_BMP,6,4),IF(AND(D8="Wet Swale",E8="—"),INDEX(PARAMS_BMP,7,4),""))))))),"") | V8: =IFERROR(IF(OR(E8="Enhanced",E8="Enhanced w/ Underdrain"),VLOOKUP(IF(SUMIFS('CDA'!$E$4:$E$53,'CDA'!$A$4:$A$53,C8,'CDA'!$D$4:$D$53,"D")>0,"D",IF(SUMIFS('CDA'!$E$4:$E$53,'CDA'!$A$4:$A$53,C8,'CDA'!$D$4:$D$53,"C")>0,"C",IF(SUMIFS('CDA'!$E$4:$E$53,'CDA'!$A$4:$A$53,C8,'CDA'!$D$4:$D$53,"B")>0,"B",IF(SUMIFS('CDA'!$E$4:$E$53,'CDA'!$A$4:$A$53,C8,'CDA'!$D$4:$D$53,"A")>0,"A","")))),PARAMS_Ksat,2,FALSE),0),0) | W8: =IFERROR(P8*(Q8*R8+S8*T8+U8),0) | X8: =IFERROR(IF(V8=0,"",(Q8+S8)/V8),"") | AA8: =IFERROR(Y8+Z8,0) | AH8: =IFERROR(AB8*INDEX(PARAMS_Trees,1,3)+AC8*INDEX(PARAMS_Trees,2,3)+AD8*INDEX(PARAMS_Trees,3,3)+AE8*INDEX(PARAMS_Trees,4,3)+AF8*INDEX(PARAMS_Trees,5,3)+AG8*INDEX(PARAMS_Trees,6,3),0) | AI8: =IFERROR(K8+W8+AA8,0) | AJ8: =IFERROR(IF(AND(D8="Permeable Pavement",E8="Enhanced"),INDEX(PARAMS_BMP,1,6),IF(AND(D8="Permeable Pavement",E8="Underdrained Enhanced"),INDEX(PARAMS_BMP,2,6),IF(AND(D8="Bioretention",E8="Standard"),INDEX(PARAMS_BMP,3,6),IF(AND(D8="Bioretention",E8="Enhanced"),INDEX(PARAMS_BMP,4,6),IF(AND(D8="Bioretention",E8="Enhanced w/ Underdrain"),INDEX(PARAMS_BMP,5,6),IF(AND(D8="Dry Swale",E8="—"),INDEX(PARAMS_BMP,6,6),IF(AND(D8="Wet Swale",E8="—"),INDEX(PARAMS_BMP,7,6),""))))))),"") | AK8: =IFERROR(AI8*AJ8+AH8,0) | AL8: =IFERROR(VLOOKUP(C8,'CDA'!$A$58:$D$67,4,FALSE),0) | AM8: =IFERROR(IF(AL8=0,AK8,MIN(AK8,AL8)),0)
I9: =IFERROR(IF(OR(E9="Enhanced",E9="Underdrained Enhanced"),VLOOKUP(IF(SUMIFS('CDA'!$E$4:$E$53,'CDA'!$A$4:$A$53,C9,'CDA'!$D$4:$D$53,"D")>0,"D",IF(SUMIFS('CDA'!$E$4:$E$53,'CDA'!$A$4:$A$53,C9,'CDA'!$D$4:$D$53,"C")>0,"C",IF(SUMIFS('CDA'!$E$4:$E$53,'CDA'!$A$4:$A$53,C9,'CDA'!$D$4:$D$53,"B")>0,"B",IF(SUMIFS('CDA'!$E$4:$E$53,'CDA'!$A$4:$A$53,C9,'CDA'!$D$4:$D$53,"A")>0,"A","")))),PARAMS_Ksat,2,FALSE),0),0) | J9: =IFERROR(IF(AND(D9="Permeable Pavement",E9="Enhanced"),INDEX(PARAMS_BMP,1,5),IF(AND(D9="Permeable Pavement",E9="Underdrained Enhanced"),INDEX(PARAMS_BMP,2,5),IF(AND(D9="Bioretention",E9="Standard"),INDEX(PARAMS_BMP,3,5),IF(AND(D9="Bioretention",E9="Enhanced"),INDEX(PARAMS_BMP,4,5),IF(AND(D9="Bioretention",E9="Enhanced w/ Underdrain"),INDEX(PARAMS_BMP,5,5),IF(AND(D9="Dry Swale",E9="—"),INDEX(PARAMS_BMP,6,5),IF(AND(D9="Wet Swale",E9="—"),INDEX(PARAMS_BMP,7,5),""))))))),"") | K9: =IFERROR(F9*G9*J9,0) | L9: =IFERROR(IF(I9=0,"",G9/I9),"") | M9: =IFERROR(IF(L9="","",IF(L9<=2,"✓","✗")),"") | P9: =IFERROR((N9+O9)/2,0) | R9: =IFERROR(IF(AND(D9="Permeable Pavement",E9="Enhanced"),INDEX(PARAMS_BMP,1,3),IF(AND(D9="Permeable Pavement",E9="Underdrained Enhanced"),INDEX(PARAMS_BMP,2,3),IF(AND(D9="Bioretention",E9="Standard"),INDEX(PARAMS_BMP,3,3),IF(AND(D9="Bioretention",E9="Enhanced"),INDEX(PARAMS_BMP,4,3),IF(AND(D9="Bioretention",E9="Enhanced w/ Underdrain"),INDEX(PARAMS_BMP,5,3),IF(AND(D9="Dry Swale",E9="—"),INDEX(PARAMS_BMP,6,3),IF(AND(D9="Wet Swale",E9="—"),INDEX(PARAMS_BMP,7,3),""))))))),"") | T9: =IFERROR(IF(AND(D9="Permeable Pavement",E9="Enhanced"),INDEX(PARAMS_BMP,1,4),IF(AND(D9="Permeable Pavement",E9="Underdrained Enhanced"),INDEX(PARAMS_BMP,2,4),IF(AND(D9="Bioretention",E9="Standard"),INDEX(PARAMS_BMP,3,4),IF(AND(D9="Bioretention",E9="Enhanced"),INDEX(PARAMS_BMP,4,4),IF(AND(D9="Bioretention",E9="Enhanced w/ Underdrain"),INDEX(PARAMS_BMP,5,4),IF(AND(D9="Dry Swale",E9="—"),INDEX(PARAMS_BMP,6,4),IF(AND(D9="Wet Swale",E9="—"),INDEX(PARAMS_BMP,7,4),""))))))),"") | V9: =IFERROR(IF(OR(E9="Enhanced",E9="Enhanced w/ Underdrain"),VLOOKUP(IF(SUMIFS('CDA'!$E$4:$E$53,'CDA'!$A$4:$A$53,C9,'CDA'!$D$4:$D$53,"D")>0,"D",IF(SUMIFS('CDA'!$E$4:$E$53,'CDA'!$A$4:$A$53,C9,'CDA'!$D$4:$D$53,"C")>0,"C",IF(SUMIFS('CDA'!$E$4:$E$53,'CDA'!$A$4:$A$53,C9,'CDA'!$D$4:$D$53,"B")>0,"B",IF(SUMIFS('CDA'!$E$4:$E$53,'CDA'!$A$4:$A$53,C9,'CDA'!$D$4:$D$53,"A")>0,"A","")))),PARAMS_Ksat,2,FALSE),0),0) | W9: =IFERROR(P9*(Q9*R9+S9*T9+U9),0) | X9: =IFERROR(IF(V9=0,"",(Q9+S9)/V9),"") | AA9: =IFERROR(Y9+Z9,0) | AH9: =IFERROR(AB9*INDEX(PARAMS_Trees,1,3)+AC9*INDEX(PARAMS_Trees,2,3)+AD9*INDEX(PARAMS_Trees,3,3)+AE9*INDEX(PARAMS_Trees,4,3)+AF9*INDEX(PARAMS_Trees,5,3)+AG9*INDEX(PARAMS_Trees,6,3),0) | AI9: =IFERROR(K9+W9+AA9,0) | AJ9: =IFERROR(IF(AND(D9="Permeable Pavement",E9="Enhanced"),INDEX(PARAMS_BMP,1,6),IF(AND(D9="Permeable Pavement",E9="Underdrained Enhanced"),INDEX(PARAMS_BMP,2,6),IF(AND(D9="Bioretention",E9="Standard"),INDEX(PARAMS_BMP,3,6),IF(AND(D9="Bioretention",E9="Enhanced"),INDEX(PARAMS_BMP,4,6),IF(AND(D9="Bioretention",E9="Enhanced w/ Underdrain"),INDEX(PARAMS_BMP,5,6),IF(AND(D9="Dry Swale",E9="—"),INDEX(PARAMS_BMP,6,6),IF(AND(D9="Wet Swale",E9="—"),INDEX(PARAMS_BMP,7,6),""))))))),"") | AK9: =IFERROR(AI9*AJ9+AH9,0) | AL9: =IFERROR(VLOOKUP(C9,'CDA'!$A$58:$D$67,4,FALSE),0) | AM9: =IFERROR(IF(AL9=0,AK9,MIN(AK9,AL9)),0)
I10: =IFERROR(IF(OR(E10="Enhanced",E10="Underdrained Enhanced"),VLOOKUP(IF(SUMIFS('CDA'!$E$4:$E$53,'CDA'!$A$4:$A$53,C10,'CDA'!$D$4:$D$53,"D")>0,"D",IF(SUMIFS('CDA'!$E$4:$E$53,'CDA'!$A$4:$A$53,C10,'CDA'!$D$4:$D$53,"C")>0,"C",IF(SUMIFS('CDA'!$E$4:$E$53,'CDA'!$A$4:$A$53,C10,'CDA'!$D$4:$D$53,"B")>0,"B",IF(SUMIFS('CDA'!$E$4:$E$53,'CDA'!$A$4:$A$53,C10,'CDA'!$D$4:$D$53,"A")>0,"A","")))),PARAMS_Ksat,2,FALSE),0),0) | J10: =IFERROR(IF(AND(D10="Permeable Pavement",E10="Enhanced"),INDEX(PARAMS_BMP,1,5),IF(AND(D10="Permeable Pavement",E10="Underdrained Enhanced"),INDEX(PARAMS_BMP,2,5),IF(AND(D10="Bioretention",E10="Standard"),INDEX(PARAMS_BMP,3,5),IF(AND(D10="Bioretention",E10="Enhanced"),INDEX(PARAMS_BMP,4,5),IF(AND(D10="Bioretention",E10="Enhanced w/ Underdrain"),INDEX(PARAMS_BMP,5,5),IF(AND(D10="Dry Swale",E10="—"),INDEX(PARAMS_BMP,6,5),IF(AND(D10="Wet Swale",E10="—"),INDEX(PARAMS_BMP,7,5),""))))))),"") | K10: =IFERROR(F10*G10*J10,0) | L10: =IFERROR(IF(I10=0,"",G10/I10),"") | M10: =IFERROR(IF(L10="","",IF(L10<=2,"✓","✗")),"") | P10: =IFERROR((N10+O10)/2,0) | R10: =IFERROR(IF(AND(D10="Permeable Pavement",E10="Enhanced"),INDEX(PARAMS_BMP,1,3),IF(AND(D10="Permeable Pavement",E10="Underdrained Enhanced"),INDEX(PARAMS_BMP,2,3),IF(AND(D10="Bioretention",E10="Standard"),INDEX(PARAMS_BMP,3,3),IF(AND(D10="Bioretention",E10="Enhanced"),INDEX(PARAMS_BMP,4,3),IF(AND(D10="Bioretention",E10="Enhanced w/ Underdrain"),INDEX(PARAMS_BMP,5,3),IF(AND(D10="Dry Swale",E10="—"),INDEX(PARAMS_BMP,6,3),IF(AND(D10="Wet Swale",E10="—"),INDEX(PARAMS_BMP,7,3),""))))))),"") | T10: =IFERROR(IF(AND(D10="Permeable Pavement",E10="Enhanced"),INDEX(PARAMS_BMP,1,4),IF(AND(D10="Permeable Pavement",E10="Underdrained Enhanced"),INDEX(PARAMS_BMP,2,4),IF(AND(D10="Bioretention",E10="Standard"),INDEX(PARAMS_BMP,3,4),IF(AND(D10="Bioretention",E10="Enhanced"),INDEX(PARAMS_BMP,4,4),IF(AND(D10="Bioretention",E10="Enhanced w/ Underdrain"),INDEX(PARAMS_BMP,5,4),IF(AND(D10="Dry Swale",E10="—"),INDEX(PARAMS_BMP,6,4),IF(AND(D10="Wet Swale",E10="—"),INDEX(PARAMS_BMP,7,4),""))))))),"") | V10: =IFERROR(IF(OR(E10="Enhanced",E10="Enhanced w/ Underdrain"),VLOOKUP(IF(SUMIFS('CDA'!$E$4:$E$53,'CDA'!$A$4:$A$53,C10,'CDA'!$D$4:$D$53,"D")>0,"D",IF(SUMIFS('CDA'!$E$4:$E$53,'CDA'!$A$4:$A$53,C10,'CDA'!$D$4:$D$53,"C")>0,"C",IF(SUMIFS('CDA'!$E$4:$E$53,'CDA'!$A$4:$A$53,C10,'CDA'!$D$4:$D$53,"B")>0,"B",IF(SUMIFS('CDA'!$E$4:$E$53,'CDA'!$A$4:$A$53,C10,'CDA'!$D$4:$D$53,"A")>0,"A","")))),PARAMS_Ksat,2,FALSE),0),0) | W10: =IFERROR(P10*(Q10*R10+S10*T10+U10),0) | X10: =IFERROR(IF(V10=0,"",(Q10+S10)/V10),"") | AA10: =IFERROR(Y10+Z10,0) | AH10: =IFERROR(AB10*INDEX(PARAMS_Trees,1,3)+AC10*INDEX(PARAMS_Trees,2,3)+AD10*INDEX(PARAMS_Trees,3,3)+AE10*INDEX(PARAMS_Trees,4,3)+AF10*INDEX(PARAMS_Trees,5,3)+AG10*INDEX(PARAMS_Trees,6,3),0) | AI10: =IFERROR(K10+W10+AA10,0) | AJ10: =IFERROR(IF(AND(D10="Permeable Pavement",E10="Enhanced"),INDEX(PARAMS_BMP,1,6),IF(AND(D10="Permeable Pavement",E10="Underdrained Enhanced"),INDEX(PARAMS_BMP,2,6),IF(AND(D10="Bioretention",E10="Standard"),INDEX(PARAMS_BMP,3,6),IF(AND(D10="Bioretention",E10="Enhanced"),INDEX(PARAMS_BMP,4,6),IF(AND(D10="Bioretention",E10="Enhanced w/ Underdrain"),INDEX(PARAMS_BMP,5,6),IF(AND(D10="Dry Swale",E10="—"),INDEX(PARAMS_BMP,6,6),IF(AND(D10="Wet Swale",E10="—"),INDEX(PARAMS_BMP,7,6),""))))))),"") | AK10: =IFERROR(AI10*AJ10+AH10,0) | AL10: =IFERROR(VLOOKUP(C10,'CDA'!$A$58:$D$67,4,FALSE),0) | AM10: =IFERROR(IF(AL10=0,AK10,MIN(AK10,AL10)),0)
I11: =IFERROR(IF(OR(E11="Enhanced",E11="Underdrained Enhanced"),VLOOKUP(IF(SUMIFS('CDA'!$E$4:$E$53,'CDA'!$A$4:$A$53,C11,'CDA'!$D$4:$D$53,"D")>0,"D",IF(SUMIFS('CDA'!$E$4:$E$53,'CDA'!$A$4:$A$53,C11,'CDA'!$D$4:$D$53,"C")>0,"C",IF(SUMIFS('CDA'!$E$4:$E$53,'CDA'!$A$4:$A$53,C11,'CDA'!$D$4:$D$53,"B")>0,"B",IF(SUMIFS('CDA'!$E$4:$E$53,'CDA'!$A$4:$A$53,C11,'CDA'!$D$4:$D$53,"A")>0,"A","")))),PARAMS_Ksat,2,FALSE),0),0) | J11: =IFERROR(IF(AND(D11="Permeable Pavement",E11="Enhanced"),INDEX(PARAMS_BMP,1,5),IF(AND(D11="Permeable Pavement",E11="Underdrained Enhanced"),INDEX(PARAMS_BMP,2,5),IF(AND(D11="Bioretention",E11="Standard"),INDEX(PARAMS_BMP,3,5),IF(AND(D11="Bioretention",E11="Enhanced"),INDEX(PARAMS_BMP,4,5),IF(AND(D11="Bioretention",E11="Enhanced w/ Underdrain"),INDEX(PARAMS_BMP,5,5),IF(AND(D11="Dry Swale",E11="—"),INDEX(PARAMS_BMP,6,5),IF(AND(D11="Wet Swale",E11="—"),INDEX(PARAMS_BMP,7,5),""))))))),"") | K11: =IFERROR(F11*G11*J11,0) | L11: =IFERROR(IF(I11=0,"",G11/I11),"") | M11: =IFERROR(IF(L11="","",IF(L11<=2,"✓","✗")),"") | P11: =IFERROR((N11+O11)/2,0) | R11: =IFERROR(IF(AND(D11="Permeable Pavement",E11="Enhanced"),INDEX(PARAMS_BMP,1,3),IF(AND(D11="Permeable Pavement",E11="Underdrained Enhanced"),INDEX(PARAMS_BMP,2,3),IF(AND(D11="Bioretention",E11="Standard"),INDEX(PARAMS_BMP,3,3),IF(AND(D11="Bioretention",E11="Enhanced"),INDEX(PARAMS_BMP,4,3),IF(AND(D11="Bioretention",E11="Enhanced w/ Underdrain"),INDEX(PARAMS_BMP,5,3),IF(AND(D11="Dry Swale",E11="—"),INDEX(PARAMS_BMP,6,3),IF(AND(D11="Wet Swale",E11="—"),INDEX(PARAMS_BMP,7,3),""))))))),"") | T11: =IFERROR(IF(AND(D11="Permeable Pavement",E11="Enhanced"),INDEX(PARAMS_BMP,1,4),IF(AND(D11="Permeable Pavement",E11="Underdrained Enhanced"),INDEX(PARAMS_BMP,2,4),IF(AND(D11="Bioretention",E11="Standard"),INDEX(PARAMS_BMP,3,4),IF(AND(D11="Bioretention",E11="Enhanced"),INDEX(PARAMS_BMP,4,4),IF(AND(D11="Bioretention",E11="Enhanced w/ Underdrain"),INDEX(PARAMS_BMP,5,4),IF(AND(D11="Dry Swale",E11="—"),INDEX(PARAMS_BMP,6,4),IF(AND(D11="Wet Swale",E11="—"),INDEX(PARAMS_BMP,7,4),""))))))),"") | V11: =IFERROR(IF(OR(E11="Enhanced",E11="Enhanced w/ Underdrain"),VLOOKUP(IF(SUMIFS('CDA'!$E$4:$E$53,'CDA'!$A$4:$A$53,C11,'CDA'!$D$4:$D$53,"D")>0,"D",IF(SUMIFS('CDA'!$E$4:$E$53,'CDA'!$A$4:$A$53,C11,'CDA'!$D$4:$D$53,"C")>0,"C",IF(SUMIFS('CDA'!$E$4:$E$53,'CDA'!$A$4:$A$53,C11,'CDA'!$D$4:$D$53,"B")>0,"B",IF(SUMIFS('CDA'!$E$4:$E$53,'CDA'!$A$4:$A$53,C11,'CDA'!$D$4:$D$53,"A")>0,"A","")))),PARAMS_Ksat,2,FALSE),0),0) | W11: =IFERROR(P11*(Q11*R11+S11*T11+U11),0) | X11: =IFERROR(IF(V11=0,"",(Q11+S11)/V11),"") | AA11: =IFERROR(Y11+Z11,0) | AH11: =IFERROR(AB11*INDEX(PARAMS_Trees,1,3)+AC11*INDEX(PARAMS_Trees,2,3)+AD11*INDEX(PARAMS_Trees,3,3)+AE11*INDEX(PARAMS_Trees,4,3)+AF11*INDEX(PARAMS_Trees,5,3)+AG11*INDEX(PARAMS_Trees,6,3),0) | AI11: =IFERROR(K11+W11+AA11,0) | AJ11: =IFERROR(IF(AND(D11="Permeable Pavement",E11="Enhanced"),INDEX(PARAMS_BMP,1,6),IF(AND(D11="Permeable Pavement",E11="Underdrained Enhanced"),INDEX(PARAMS_BMP,2,6),IF(AND(D11="Bioretention",E11="Standard"),INDEX(PARAMS_BMP,3,6),IF(AND(D11="Bioretention",E11="Enhanced"),INDEX(PARAMS_BMP,4,6),IF(AND(D11="Bioretention",E11="Enhanced w/ Underdrain"),INDEX(PARAMS_BMP,5,6),IF(AND(D11="Dry Swale",E11="—"),INDEX(PARAMS_BMP,6,6),IF(AND(D11="Wet Swale",E11="—"),INDEX(PARAMS_BMP,7,6),""))))))),"") | AK11: =IFERROR(AI11*AJ11+AH11,0) | AL11: =IFERROR(VLOOKUP(C11,'CDA'!$A$58:$D$67,4,FALSE),0) | AM11: =IFERROR(IF(AL11=0,AK11,MIN(AK11,AL11)),0)
I12: =IFERROR(IF(OR(E12="Enhanced",E12="Underdrained Enhanced"),VLOOKUP(IF(SUMIFS('CDA'!$E$4:$E$53,'CDA'!$A$4:$A$53,C12,'CDA'!$D$4:$D$53,"D")>0,"D",IF(SUMIFS('CDA'!$E$4:$E$53,'CDA'!$A$4:$A$53,C12,'CDA'!$D$4:$D$53,"C")>0,"C",IF(SUMIFS('CDA'!$E$4:$E$53,'CDA'!$A$4:$A$53,C12,'CDA'!$D$4:$D$53,"B")>0,"B",IF(SUMIFS('CDA'!$E$4:$E$53,'CDA'!$A$4:$A$53,C12,'CDA'!$D$4:$D$53,"A")>0,"A","")))),PARAMS_Ksat,2,FALSE),0),0) | J12: =IFERROR(IF(AND(D12="Permeable Pavement",E12="Enhanced"),INDEX(PARAMS_BMP,1,5),IF(AND(D12="Permeable Pavement",E12="Underdrained Enhanced"),INDEX(PARAMS_BMP,2,5),IF(AND(D12="Bioretention",E12="Standard"),INDEX(PARAMS_BMP,3,5),IF(AND(D12="Bioretention",E12="Enhanced"),INDEX(PARAMS_BMP,4,5),IF(AND(D12="Bioretention",E12="Enhanced w/ Underdrain"),INDEX(PARAMS_BMP,5,5),IF(AND(D12="Dry Swale",E12="—"),INDEX(PARAMS_BMP,6,5),IF(AND(D12="Wet Swale",E12="—"),INDEX(PARAMS_BMP,7,5),""))))))),"") | K12: =IFERROR(F12*G12*J12,0) | L12: =IFERROR(IF(I12=0,"",G12/I12),"") | M12: =IFERROR(IF(L12="","",IF(L12<=2,"✓","✗")),"") | P12: =IFERROR((N12+O12)/2,0) | R12: =IFERROR(IF(AND(D12="Permeable Pavement",E12="Enhanced"),INDEX(PARAMS_BMP,1,3),IF(AND(D12="Permeable Pavement",E12="Underdrained Enhanced"),INDEX(PARAMS_BMP,2,3),IF(AND(D12="Bioretention",E12="Standard"),INDEX(PARAMS_BMP,3,3),IF(AND(D12="Bioretention",E12="Enhanced"),INDEX(PARAMS_BMP,4,3),IF(AND(D12="Bioretention",E12="Enhanced w/ Underdrain"),INDEX(PARAMS_BMP,5,3),IF(AND(D12="Dry Swale",E12="—"),INDEX(PARAMS_BMP,6,3),IF(AND(D12="Wet Swale",E12="—"),INDEX(PARAMS_BMP,7,3),""))))))),"") | T12: =IFERROR(IF(AND(D12="Permeable Pavement",E12="Enhanced"),INDEX(PARAMS_BMP,1,4),IF(AND(D12="Permeable Pavement",E12="Underdrained Enhanced"),INDEX(PARAMS_BMP,2,4),IF(AND(D12="Bioretention",E12="Standard"),INDEX(PARAMS_BMP,3,4),IF(AND(D12="Bioretention",E12="Enhanced"),INDEX(PARAMS_BMP,4,4),IF(AND(D12="Bioretention",E12="Enhanced w/ Underdrain"),INDEX(PARAMS_BMP,5,4),IF(AND(D12="Dry Swale",E12="—"),INDEX(PARAMS_BMP,6,4),IF(AND(D12="Wet Swale",E12="—"),INDEX(PARAMS_BMP,7,4),""))))))),"") | V12: =IFERROR(IF(OR(E12="Enhanced",E12="Enhanced w/ Underdrain"),VLOOKUP(IF(SUMIFS('CDA'!$E$4:$E$53,'CDA'!$A$4:$A$53,C12,'CDA'!$D$4:$D$53,"D")>0,"D",IF(SUMIFS('CDA'!$E$4:$E$53,'CDA'!$A$4:$A$53,C12,'CDA'!$D$4:$D$53,"C")>0,"C",IF(SUMIFS('CDA'!$E$4:$E$53,'CDA'!$A$4:$A$53,C12,'CDA'!$D$4:$D$53,"B")>0,"B",IF(SUMIFS('CDA'!$E$4:$E$53,'CDA'!$A$4:$A$53,C12,'CDA'!$D$4:$D$53,"A")>0,"A","")))),PARAMS_Ksat,2,FALSE),0),0) | W12: =IFERROR(P12*(Q12*R12+S12*T12+U12),0) | X12: =IFERROR(IF(V12=0,"",(Q12+S12)/V12),"") | AA12: =IFERROR(Y12+Z12,0) | AH12: =IFERROR(AB12*INDEX(PARAMS_Trees,1,3)+AC12*INDEX(PARAMS_Trees,2,3)+AD12*INDEX(PARAMS_Trees,3,3)+AE12*INDEX(PARAMS_Trees,4,3)+AF12*INDEX(PARAMS_Trees,5,3)+AG12*INDEX(PARAMS_Trees,6,3),0) | AI12: =IFERROR(K12+W12+AA12,0) | AJ12: =IFERROR(IF(AND(D12="Permeable Pavement",E12="Enhanced"),INDEX(PARAMS_BMP,1,6),IF(AND(D12="Permeable Pavement",E12="Underdrained Enhanced"),INDEX(PARAMS_BMP,2,6),IF(AND(D12="Bioretention",E12="Standard"),INDEX(PARAMS_BMP,3,6),IF(AND(D12="Bioretention",E12="Enhanced"),INDEX(PARAMS_BMP,4,6),IF(AND(D12="Bioretention",E12="Enhanced w/ Underdrain"),INDEX(PARAMS_BMP,5,6),IF(AND(D12="Dry Swale",E12="—"),INDEX(PARAMS_BMP,6,6),IF(AND(D12="Wet Swale",E12="—"),INDEX(PARAMS_BMP,7,6),""))))))),"") | AK12: =IFERROR(AI12*AJ12+AH12,0) | AL12: =IFERROR(VLOOKUP(C12,'CDA'!$A$58:$D$67,4,FALSE),0) | AM12: =IFERROR(IF(AL12=0,AK12,MIN(AK12,AL12)),0)
I13: =IFERROR(IF(OR(E13="Enhanced",E13="Underdrained Enhanced"),VLOOKUP(IF(SUMIFS('CDA'!$E$4:$E$53,'CDA'!$A$4:$A$53,C13,'CDA'!$D$4:$D$53,"D")>0,"D",IF(SUMIFS('CDA'!$E$4:$E$53,'CDA'!$A$4:$A$53,C13,'CDA'!$D$4:$D$53,"C")>0,"C",IF(SUMIFS('CDA'!$E$4:$E$53,'CDA'!$A$4:$A$53,C13,'CDA'!$D$4:$D$53,"B")>0,"B",IF(SUMIFS('CDA'!$E$4:$E$53,'CDA'!$A$4:$A$53,C13,'CDA'!$D$4:$D$53,"A")>0,"A","")))),PARAMS_Ksat,2,FALSE),0),0) | J13: =IFERROR(IF(AND(D13="Permeable Pavement",E13="Enhanced"),INDEX(PARAMS_BMP,1,5),IF(AND(D13="Permeable Pavement",E13="Underdrained Enhanced"),INDEX(PARAMS_BMP,2,5),IF(AND(D13="Bioretention",E13="Standard"),INDEX(PARAMS_BMP,3,5),IF(AND(D13="Bioretention",E13="Enhanced"),INDEX(PARAMS_BMP,4,5),IF(AND(D13="Bioretention",E13="Enhanced w/ Underdrain"),INDEX(PARAMS_BMP,5,5),IF(AND(D13="Dry Swale",E13="—"),INDEX(PARAMS_BMP,6,5),IF(AND(D13="Wet Swale",E13="—"),INDEX(PARAMS_BMP,7,5),""))))))),"") | K13: =IFERROR(F13*G13*J13,0) | L13: =IFERROR(IF(I13=0,"",G13/I13),"") | M13: =IFERROR(IF(L13="","",IF(L13<=2,"✓","✗")),"") | P13: =IFERROR((N13+O13)/2,0) | R13: =IFERROR(IF(AND(D13="Permeable Pavement",E13="Enhanced"),INDEX(PARAMS_BMP,1,3),IF(AND(D13="Permeable Pavement",E13="Underdrained Enhanced"),INDEX(PARAMS_BMP,2,3),IF(AND(D13="Bioretention",E13="Standard"),INDEX(PARAMS_BMP,3,3),IF(AND(D13="Bioretention",E13="Enhanced"),INDEX(PARAMS_BMP,4,3),IF(AND(D13="Bioretention",E13="Enhanced w/ Underdrain"),INDEX(PARAMS_BMP,5,3),IF(AND(D13="Dry Swale",E13="—"),INDEX(PARAMS_BMP,6,3),IF(AND(D13="Wet Swale",E13="—"),INDEX(PARAMS_BMP,7,3),""))))))),"") | T13: =IFERROR(IF(AND(D13="Permeable Pavement",E13="Enhanced"),INDEX(PARAMS_BMP,1,4),IF(AND(D13="Permeable Pavement",E13="Underdrained Enhanced"),INDEX(PARAMS_BMP,2,4),IF(AND(D13="Bioretention",E13="Standard"),INDEX(PARAMS_BMP,3,4),IF(AND(D13="Bioretention",E13="Enhanced"),INDEX(PARAMS_BMP,4,4),IF(AND(D13="Bioretention",E13="Enhanced w/ Underdrain"),INDEX(PARAMS_BMP,5,4),IF(AND(D13="Dry Swale",E13="—"),INDEX(PARAMS_BMP,6,4),IF(AND(D13="Wet Swale",E13="—"),INDEX(PARAMS_BMP,7,4),""))))))),"") | V13: =IFERROR(IF(OR(E13="Enhanced",E13="Enhanced w/ Underdrain"),VLOOKUP(IF(SUMIFS('CDA'!$E$4:$E$53,'CDA'!$A$4:$A$53,C13,'CDA'!$D$4:$D$53,"D")>0,"D",IF(SUMIFS('CDA'!$E$4:$E$53,'CDA'!$A$4:$A$53,C13,'CDA'!$D$4:$D$53,"C")>0,"C",IF(SUMIFS('CDA'!$E$4:$E$53,'CDA'!$A$4:$A$53,C13,'CDA'!$D$4:$D$53,"B")>0,"B",IF(SUMIFS('CDA'!$E$4:$E$53,'CDA'!$A$4:$A$53,C13,'CDA'!$D$4:$D$53,"A")>0,"A","")))),PARAMS_Ksat,2,FALSE),0),0) | W13: =IFERROR(P13*(Q13*R13+S13*T13+U13),0) | X13: =IFERROR(IF(V13=0,"",(Q13+S13)/V13),"") | AA13: =IFERROR(Y13+Z13,0) | AH13: =IFERROR(AB13*INDEX(PARAMS_Trees,1,3)+AC13*INDEX(PARAMS_Trees,2,3)+AD13*INDEX(PARAMS_Trees,3,3)+AE13*INDEX(PARAMS_Trees,4,3)+AF13*INDEX(PARAMS_Trees,5,3)+AG13*INDEX(PARAMS_Trees,6,3),0) | AI13: =IFERROR(K13+W13+AA13,0) | AJ13: =IFERROR(IF(AND(D13="Permeable Pavement",E13="Enhanced"),INDEX(PARAMS_BMP,1,6),IF(AND(D13="Permeable Pavement",E13="Underdrained Enhanced"),INDEX(PARAMS_BMP,2,6),IF(AND(D13="Bioretention",E13="Standard"),INDEX(PARAMS_BMP,3,6),IF(AND(D13="Bioretention",E13="Enhanced"),INDEX(PARAMS_BMP,4,6),IF(AND(D13="Bioretention",E13="Enhanced w/ Underdrain"),INDEX(PARAMS_BMP,5,6),IF(AND(D13="Dry Swale",E13="—"),INDEX(PARAMS_BMP,6,6),IF(AND(D13="Wet Swale",E13="—"),INDEX(PARAMS_BMP,7,6),""))))))),"") | AK13: =IFERROR(AI13*AJ13+AH13,0) | AL13: =IFERROR(VLOOKUP(C13,'CDA'!$A$58:$D$67,4,FALSE),0) | AM13: =IFERROR(IF(AL13=0,AK13,MIN(AK13,AL13)),0)
I14: =IFERROR(IF(OR(E14="Enhanced",E14="Underdrained Enhanced"),VLOOKUP(IF(SUMIFS('CDA'!$E$4:$E$53,'CDA'!$A$4:$A$53,C14,'CDA'!$D$4:$D$53,"D")>0,"D",IF(SUMIFS('CDA'!$E$4:$E$53,'CDA'!$A$4:$A$53,C14,'CDA'!$D$4:$D$53,"C")>0,"C",IF(SUMIFS('CDA'!$E$4:$E$53,'CDA'!$A$4:$A$53,C14,'CDA'!$D$4:$D$53,"B")>0,"B",IF(SUMIFS('CDA'!$E$4:$E$53,'CDA'!$A$4:$A$53,C14,'CDA'!$D$4:$D$53,"A")>0,"A","")))),PARAMS_Ksat,2,FALSE),0),0) | J14: =IFERROR(IF(AND(D14="Permeable Pavement",E14="Enhanced"),INDEX(PARAMS_BMP,1,5),IF(AND(D14="Permeable Pavement",E14="Underdrained Enhanced"),INDEX(PARAMS_BMP,2,5),IF(AND(D14="Bioretention",E14="Standard"),INDEX(PARAMS_BMP,3,5),IF(AND(D14="Bioretention",E14="Enhanced"),INDEX(PARAMS_BMP,4,5),IF(AND(D14="Bioretention",E14="Enhanced w/ Underdrain"),INDEX(PARAMS_BMP,5,5),IF(AND(D14="Dry Swale",E14="—"),INDEX(PARAMS_BMP,6,5),IF(AND(D14="Wet Swale",E14="—"),INDEX(PARAMS_BMP,7,5),""))))))),"") | K14: =IFERROR(F14*G14*J14,0) | L14: =IFERROR(IF(I14=0,"",G14/I14),"") | M14: =IFERROR(IF(L14="","",IF(L14<=2,"✓","✗")),"") | P14: =IFERROR((N14+O14)/2,0) | R14: =IFERROR(IF(AND(D14="Permeable Pavement",E14="Enhanced"),INDEX(PARAMS_BMP,1,3),IF(AND(D14="Permeable Pavement",E14="Underdrained Enhanced"),INDEX(PARAMS_BMP,2,3),IF(AND(D14="Bioretention",E14="Standard"),INDEX(PARAMS_BMP,3,3),IF(AND(D14="Bioretention",E14="Enhanced"),INDEX(PARAMS_BMP,4,3),IF(AND(D14="Bioretention",E14="Enhanced w/ Underdrain"),INDEX(PARAMS_BMP,5,3),IF(AND(D14="Dry Swale",E14="—"),INDEX(PARAMS_BMP,6,3),IF(AND(D14="Wet Swale",E14="—"),INDEX(PARAMS_BMP,7,3),""))))))),"") | T14: =IFERROR(IF(AND(D14="Permeable Pavement",E14="Enhanced"),INDEX(PARAMS_BMP,1,4),IF(AND(D14="Permeable Pavement",E14="Underdrained Enhanced"),INDEX(PARAMS_BMP,2,4),IF(AND(D14="Bioretention",E14="Standard"),INDEX(PARAMS_BMP,3,4),IF(AND(D14="Bioretention",E14="Enhanced"),INDEX(PARAMS_BMP,4,4),IF(AND(D14="Bioretention",E14="Enhanced w/ Underdrain"),INDEX(PARAMS_BMP,5,4),IF(AND(D14="Dry Swale",E14="—"),INDEX(PARAMS_BMP,6,4),IF(AND(D14="Wet Swale",E14="—"),INDEX(PARAMS_BMP,7,4),""))))))),"") | V14: =IFERROR(IF(OR(E14="Enhanced",E14="Enhanced w/ Underdrain"),VLOOKUP(IF(SUMIFS('CDA'!$E$4:$E$53,'CDA'!$A$4:$A$53,C14,'CDA'!$D$4:$D$53,"D")>0,"D",IF(SUMIFS('CDA'!$E$4:$E$53,'CDA'!$A$4:$A$53,C14,'CDA'!$D$4:$D$53,"C")>0,"C",IF(SUMIFS('CDA'!$E$4:$E$53,'CDA'!$A$4:$A$53,C14,'CDA'!$D$4:$D$53,"B")>0,"B",IF(SUMIFS('CDA'!$E$4:$E$53,'CDA'!$A$4:$A$53,C14,'CDA'!$D$4:$D$53,"A")>0,"A","")))),PARAMS_Ksat,2,FALSE),0),0) | W14: =IFERROR(P14*(Q14*R14+S14*T14+U14),0) | X14: =IFERROR(IF(V14=0,"",(Q14+S14)/V14),"") | AA14: =IFERROR(Y14+Z14,0) | AH14: =IFERROR(AB14*INDEX(PARAMS_Trees,1,3)+AC14*INDEX(PARAMS_Trees,2,3)+AD14*INDEX(PARAMS_Trees,3,3)+AE14*INDEX(PARAMS_Trees,4,3)+AF14*INDEX(PARAMS_Trees,5,3)+AG14*INDEX(PARAMS_Trees,6,3),0) | AI14: =IFERROR(K14+W14+AA14,0) | AJ14: =IFERROR(IF(AND(D14="Permeable Pavement",E14="Enhanced"),INDEX(PARAMS_BMP,1,6),IF(AND(D14="Permeable Pavement",E14="Underdrained Enhanced"),INDEX(PARAMS_BMP,2,6),IF(AND(D14="Bioretention",E14="Standard"),INDEX(PARAMS_BMP,3,6),IF(AND(D14="Bioretention",E14="Enhanced"),INDEX(PARAMS_BMP,4,6),IF(AND(D14="Bioretention",E14="Enhanced w/ Underdrain"),INDEX(PARAMS_BMP,5,6),IF(AND(D14="Dry Swale",E14="—"),INDEX(PARAMS_BMP,6,6),IF(AND(D14="Wet Swale",E14="—"),INDEX(PARAMS_BMP,7,6),""))))))),"") | AK14: =IFERROR(AI14*AJ14+AH14,0) | AL14: =IFERROR(VLOOKUP(C14,'CDA'!$A$58:$D$67,4,FALSE),0) | AM14: =IFERROR(IF(AL14=0,AK14,MIN(AK14,AL14)),0)
I15: =IFERROR(IF(OR(E15="Enhanced",E15="Underdrained Enhanced"),VLOOKUP(IF(SUMIFS('CDA'!$E$4:$E$53,'CDA'!$A$4:$A$53,C15,'CDA'!$D$4:$D$53,"D")>0,"D",IF(SUMIFS('CDA'!$E$4:$E$53,'CDA'!$A$4:$A$53,C15,'CDA'!$D$4:$D$53,"C")>0,"C",IF(SUMIFS('CDA'!$E$4:$E$53,'CDA'!$A$4:$A$53,C15,'CDA'!$D$4:$D$53,"B")>0,"B",IF(SUMIFS('CDA'!$E$4:$E$53,'CDA'!$A$4:$A$53,C15,'CDA'!$D$4:$D$53,"A")>0,"A","")))),PARAMS_Ksat,2,FALSE),0),0) | J15: =IFERROR(IF(AND(D15="Permeable Pavement",E15="Enhanced"),INDEX(PARAMS_BMP,1,5),IF(AND(D15="Permeable Pavement",E15="Underdrained Enhanced"),INDEX(PARAMS_BMP,2,5),IF(AND(D15="Bioretention",E15="Standard"),INDEX(PARAMS_BMP,3,5),IF(AND(D15="Bioretention",E15="Enhanced"),INDEX(PARAMS_BMP,4,5),IF(AND(D15="Bioretention",E15="Enhanced w/ Underdrain"),INDEX(PARAMS_BMP,5,5),IF(AND(D15="Dry Swale",E15="—"),INDEX(PARAMS_BMP,6,5),IF(AND(D15="Wet Swale",E15="—"),INDEX(PARAMS_BMP,7,5),""))))))),"") | K15: =IFERROR(F15*G15*J15,0) | L15: =IFERROR(IF(I15=0,"",G15/I15),"") | M15: =IFERROR(IF(L15="","",IF(L15<=2,"✓","✗")),"") | P15: =IFERROR((N15+O15)/2,0) | R15: =IFERROR(IF(AND(D15="Permeable Pavement",E15="Enhanced"),INDEX(PARAMS_BMP,1,3),IF(AND(D15="Permeable Pavement",E15="Underdrained Enhanced"),INDEX(PARAMS_BMP,2,3),IF(AND(D15="Bioretention",E15="Standard"),INDEX(PARAMS_BMP,3,3),IF(AND(D15="Bioretention",E15="Enhanced"),INDEX(PARAMS_BMP,4,3),IF(AND(D15="Bioretention",E15="Enhanced w/ Underdrain"),INDEX(PARAMS_BMP,5,3),IF(AND(D15="Dry Swale",E15="—"),INDEX(PARAMS_BMP,6,3),IF(AND(D15="Wet Swale",E15="—"),INDEX(PARAMS_BMP,7,3),""))))))),"") | T15: =IFERROR(IF(AND(D15="Permeable Pavement",E15="Enhanced"),INDEX(PARAMS_BMP,1,4),IF(AND(D15="Permeable Pavement",E15="Underdrained Enhanced"),INDEX(PARAMS_BMP,2,4),IF(AND(D15="Bioretention",E15="Standard"),INDEX(PARAMS_BMP,3,4),IF(AND(D15="Bioretention",E15="Enhanced"),INDEX(PARAMS_BMP,4,4),IF(AND(D15="Bioretention",E15="Enhanced w/ Underdrain"),INDEX(PARAMS_BMP,5,4),IF(AND(D15="Dry Swale",E15="—"),INDEX(PARAMS_BMP,6,4),IF(AND(D15="Wet Swale",E15="—"),INDEX(PARAMS_BMP,7,4),""))))))),"") | V15: =IFERROR(IF(OR(E15="Enhanced",E15="Enhanced w/ Underdrain"),VLOOKUP(IF(SUMIFS('CDA'!$E$4:$E$53,'CDA'!$A$4:$A$53,C15,'CDA'!$D$4:$D$53,"D")>0,"D",IF(SUMIFS('CDA'!$E$4:$E$53,'CDA'!$A$4:$A$53,C15,'CDA'!$D$4:$D$53,"C")>0,"C",IF(SUMIFS('CDA'!$E$4:$E$53,'CDA'!$A$4:$A$53,C15,'CDA'!$D$4:$D$53,"B")>0,"B",IF(SUMIFS('CDA'!$E$4:$E$53,'CDA'!$A$4:$A$53,C15,'CDA'!$D$4:$D$53,"A")>0,"A","")))),PARAMS_Ksat,2,FALSE),0),0) | W15: =IFERROR(P15*(Q15*R15+S15*T15+U15),0) | X15: =IFERROR(IF(V15=0,"",(Q15+S15)/V15),"") | AA15: =IFERROR(Y15+Z15,0) | AH15: =IFERROR(AB15*INDEX(PARAMS_Trees,1,3)+AC15*INDEX(PARAMS_Trees,2,3)+AD15*INDEX(PARAMS_Trees,3,3)+AE15*INDEX(PARAMS_Trees,4,3)+AF15*INDEX(PARAMS_Trees,5,3)+AG15*INDEX(PARAMS_Trees,6,3),0) | AI15: =IFERROR(K15+W15+AA15,0) | AJ15: =IFERROR(IF(AND(D15="Permeable Pavement",E15="Enhanced"),INDEX(PARAMS_BMP,1,6),IF(AND(D15="Permeable Pavement",E15="Underdrained Enhanced"),INDEX(PARAMS_BMP,2,6),IF(AND(D15="Bioretention",E15="Standard"),INDEX(PARAMS_BMP,3,6),IF(AND(D15="Bioretention",E15="Enhanced"),INDEX(PARAMS_BMP,4,6),IF(AND(D15="Bioretention",E15="Enhanced w/ Underdrain"),INDEX(PARAMS_BMP,5,6),IF(AND(D15="Dry Swale",E15="—"),INDEX(PARAMS_BMP,6,6),IF(AND(D15="Wet Swale",E15="—"),INDEX(PARAMS_BMP,7,6),""))))))),"") | AK15: =IFERROR(AI15*AJ15+AH15,0) | AL15: =IFERROR(VLOOKUP(C15,'CDA'!$A$58:$D$67,4,FALSE),0) | AM15: =IFERROR(IF(AL15=0,AK15,MIN(AK15,AL15)),0)
